Workbook

Sheet 抖音账单汇总
A1: 订单号 | B1: 求和项:销售收入 | C1: 已核对收入 | D1: 差异
A2: 6923064015675489559 | B2: 6 | C2: =_xlfn.XLOOKUP(A2,已核对收入!$A:$A,已核对收入!$B:$B) -> 6 | D2: =B2-C2 -> 0
A3: 6923416114502532384 | B3: -169 | C3: =_xlfn.XLOOKUP(A3,已核对收入!$A:$A,已核对收入!$B:$B) -> -169 | D3: =B3-C3 -> 0
A4: 6923455763794263484 | B4: -179 | C4: =_xlfn.XLOOKUP(A4,已核对收入!$A:$A,已核对收入!$B:$B) -> -179 | D4: =B4-C4 -> 0
A5: 6923636505633586984 | B5: 179 | C5: =_xlfn.XLOOKUP(A5,已核对收入!$A:$A,已核对收入!$B:$B) -> 179 | D5: =B5-C5 -> 0
A6: 6923640314699284416 | B6: -179 | C6: =_xlfn.XLOOKUP(A6,已核对收入!$A:$A,已核对收入!$B:$B) -> -179 | D6: =B6-C6 -> 0
A7: 6923643815047822963 | B7: 179 | C7: =_xlfn.XLOOKUP(A7,已核对收入!$A:$A,已核对收入!$B:$B) -> 179 | D7: =B7-C7 -> 0
A8: 6923652229969313434 | B8: -179 | C8: =_xlfn.XLOOKUP(A8,已核对收入!$A:$A,已核对收入!$B:$B) -> -179 | D8: =B8-C8 -> 0
A9: 6923661839766748780 | B9: -179 | C9: =_xlfn.XLOOKUP(A9,已核对收入!$A:$A,已核对收入!$B:$B) -> -179 | D9: =B9-C9 -> 0
A10: 6923667343994027127 | B10: -20.27 | C10: =_xlfn.XLOOKUP(A10,已核对收入!$A:$A,已核对收入!$B:$B) -> -20.27 | D10: =B10-C10 -> 0
A11: 6923676186043579878 | B11: 179 | C11: =_xlfn.XLOOKUP(A11,已核对收入!$A:$A,已核对收入!$B:$B) -> 179 | D11: =B11-C11 -> 0
A12: 6923691053209255280 | B12: -179 | C12: =_xlfn.XLOOKUP(A12,已核对收入!$A:$A,已核对收入!$B:$B) -> -179 | D12: =B12-C12 -> 0
A13: 6923706623434718909 | B13: 199 | C13: =_xlfn.XLOOKUP(A13,已核对收入!$A:$A,已核对收入!$B:$B) -> 199 | D13: =B13-C13 -> 0
... A2489: 总计 | B2489: 438770.18 | C2489: =_xlfn.XLOOKUP(A2489,已核对收入!$A:$A,已核对收入!$B:$B) -> 438770.18 | D2489: =B2489-C2489 -> 0

Sheet 抖音资金账单
A1: 动账时间 | B1: 动帐流水号 | C1: 动账方向 | D1: 动账金额 | E1: 动账账户 | F1: 动账场景 | G1: 计费类型 | H1: 子订单号 | I1: 订单号 | J1: 售后编号 | K1: 下单时间 | L1: 商品ID | M1: 商品名称 | N1: 达人ID | O1: 达人名称 | P1: 订单类型 | Q1: 订单实付应结 | R1: 销售收入 | S1: 运费实付 | T1: 实际平台补贴_运费 | U1: 实际平台补贴 | V1: 其他平台补贴 | W1: 以旧换新抵扣 | X1: 政府补贴平台垫资 | Y1: 实际达人补贴 | Z1: 实际抖音支付补贴 | AA1: 实际抖音月付营销补贴 | AB1: 银行补贴 | AC1: 订单退款 | AD1: 平台服务费 | AE1: 佣金 | AF1: 服务商佣金 | AG1: 渠道分成 | AH1: 招商服务费 | AI1: 站外推广费 | AJ1: 其他分成 | AK1: 是否免佣 | AL1: 免佣金额 | AM1: 备注
A2: 46054.145 | B2: '2026020103282407146092034081 | C2: 入账 | D2: 170.05 | E2: 聚合账户 | F2: 货款结算入账 | G2: 巨量千川 | H2: '6950156655091651754 | I2: '6950156655091651754 | J2: 'SS76006819130407657300061 | K2: 46044.562 | L2: '3787311554958066065 | M2: 【小火山】雪中飞儿童羽绒服冬装外套保暖冬装X2501326322FXT | P2: 普通订单 | Q2: 179 | R2: =Q2+SUM(T2:AC2) -> 179 | S2: 0 | T2: 0 | U2: 0 | V2: 0 | W2: 0 | X2: 0 | Y2: 0 | Z2: 0 | AA2: 0 | AB2: 0 | AC2: 0 | AD2: -8.95 | AE2: 0 | AF2: 0 | AG2: 0 | AH2: 0 | AI2: 0 | AJ2: 0 | AL2: 0 | AM2: 订单结算
A3: 46054.151 | B3: '2026020103374335750874114081 | C3: 入账 | D3: 170.05 | E3: 聚合账户 | F3: 货款结算入账 | G3: 小店自卖 | H3: '6950291725161993463 | I3: '6950291725161993463 | J3: 'SS76007626285014223710075 | K3: 46049.445 | L3: '3787311554958066065 | M3: 【小火山】雪中飞儿童羽绒服冬装外套保暖冬装X2501326322FXT | P3: 普通订单 | Q3: 179 | R3: =Q3+SUM(T3:AC3) -> 179 | S3: 0 | T3: 0 | U3: 0 | V3: 0 | W3: 0 | X3: 0 | Y3: 0 | Z3: 0 | AA3: 0 | AB3: 0 | AC3: 0 | AD3: -8.95 | AE3: 0 | AF3: 0 | AG3: 0 | AH3: 0 | AI3: 0 | AJ3: 0 | AL3: 0 | AM3: 订单结算
A4: 46054.151 | B4: '2026020103374439972375134081 | C4: 入账 | D4: 170.05 | E4: 聚合账户 | F4: 货款结算入账 | G4: 小店自卖 | H4: '6950169936981530544 | I4: '6950169936981530544 | J4: 'SS76006246102660592900093 | K4: 46044.429 | L4: '3787311554958066065 | M4: 【小火山】雪中飞儿童羽绒服冬装外套保暖冬装X2501326322FXT | P4: 普通订单 | Q4: 159 | R4: =Q4+SUM(T4:AC4) -> 179 | S4: 0 | T4: 0 | U4: 20 | V4: 0 | W4: 0 | X4: 0 | Y4: 0 | Z4: 0 | AA4: 0 | AB4: 0 | AC4: 0 | AD4: -8.95 | AE4: 0 | AF4: 0 | AG4: 0 | AH4: 0 | AI4: 0 | AJ4: 0 | AL4: 0 | AM4: 订单结算
A5: 46054.151 | B5: '2026020103374320567496144081 | C5: 入账 | D5: 170.05 | E5: 聚合账户 | F5: 货款结算入账 | G5: 巨量千川 | H5: '6950003137083741790 | I5: '6950003137083741790 | J5: 'SS75980830417139146760131 | K5: 46038.894 | L5: '3787311554958066065 | M5: 【小火山】雪中飞儿童羽绒服冬装外套保暖冬装X2501326322FXT | P5: 普通订单 | Q5: 159 | R5: =Q5+SUM(T5:AC5) -> 179 | S5: 0 | T5: 0 | U5: 20 | V5: 0 | W5: 0 | X5: 0 | Y5: 0 | Z5: 0 | AA5: 0 | AB5: 0 | AC5: 0 | AD5: -8.95 | AE5: 0 | AF5: 0 | AG5: 0 | AH5: 0 | AI5: 0 | AJ5: 0 | AL5: 0 | AM5: 订单结算
A6: 46054.163 | B6: '2026020103543335945685114081 | C6: 入账 | D6: 170.05 | E6: 聚合账户 | F6: 货款结算入账 | G6: 小店自卖 | H6: '6923791599134145789 | I6: '6923791599134145789 | J6: 'SS76006142717020249700005 | K6: 46043.809 | L6: '3787311554958066065 | M6: 【小火山】雪中飞儿童羽绒服冬装外套保暖冬装X2501326322FXT | P6: 普通订单 | Q6: 155.96 | R6: =Q6+SUM(T6:AC6) -> 179 | S6: 0 | T6: 0 | U6: 23.04 | V6: 0 | W6: 0 | X6: 0 | Y6: 0 | Z6: 0 | AA6: 0 | AB6: 0 | AC6: 0 | AD6: -8.95 | AE6: 0 | AF6: 0 | AG6: 0 | AH6: 0 | AI6: 0 | AJ6: 0 | AL6: 0 | AM6: 订单结算
A7: 46054.163 | B7: '2026020103544718465595424081 | C7: 入账 | D7: 170.05 | E7: 聚合账户 | F7: 货款结算入账 | G7: 巨量千川 | H7: '6923807694818541028 | I7: '6923807694818541028 | J7: 'SS76006594379889218920080 | K7: 46044.378 | L7: '3787311554958066065 | M7: 【小火山】雪中飞儿童羽绒服冬装外套保暖冬装X2501326322FXT | P7: 普通订单 | Q7: 159 | R7: =Q7+SUM(T7:AC7) -> 179 | S7: 0 | T7: 0 | U7: 20 | V7: 0 | W7: 0 | X7: 0 | Y7: 0 | Z7: 0 | AA7: 0 | AB7: 0 | AC7: 0 | AD7: -8.95 | AE7: 0 | AF7: 0 | AG7: 0 | AH7: 0 | AI7: 0 | AJ7: 0 | AL7: 0 | AM7: 订单结算
A8: 46054.169 | B8: '2026020104035203998193104081 | C8: 入账 | D8: 170.05 | E8: 聚合账户 | F8: 货款结算入账 | G8: 巨量千川 | H8: '6950133763685553252 | I8: '6950133763685553252 | J8: 'SS76005924296449395540138 | K8: 46043.903 | L8: '3787311554958066065 | M8: 【小火山】雪中飞儿童羽绒服冬装外套保暖冬装X2501326322FXT | P8: 普通订单 | Q8: 179 | R8: =Q8+SUM(T8:AC8) -> 179 | S8: 0 | T8: 0 | U8: 0 | V8: 0 | W8: 0 | X8: 0 | Y8: 0 | Z8: 0 | AA8: 0 | AB8: 0 | AC8: 0 | AD8: -8.95 | AE8: 0 | AF8: 0 | AG8: 0 | AH8: 0 | AI8: 0 | AJ8: 0 | AL8: 0 | AM8: 订单结算
A9: 46054.174 | B9: '2026020104103339605540354081 | C9: 入账 | D9: 170.05 | E9: 聚合账户 | F9: 货款结算入账 | G9: 小店自卖 | H9: '6950136311308424819 | I9: '6950136311308424819 | J9: 'SS76006163096053233140227 | K9: 46043.898 | L9: '3787311554958066065 | M9: 【小火山】雪中飞儿童羽绒服冬装外套保暖冬装X2501326322FXT | P9: 普通订单 | Q9: 169 | R9: =Q9+SUM(T9:AC9) -> 179 | S9: 0 | T9: 0 | U9: 10 | V9: 0 | W9: 0 | X9: 0 | Y9: 0 | Z9: 0 | AA9: 0 | AB9: 0 | AC9: 0 | AD9: -8.95 | AE9: 0 | AF9: 0 | AG9: 0 | AH9: 0 | AI9: 0 | AJ9: 0 | AL9: 0 | AM9: 订单结算
A10: 46054.174 | B10: '2026020104103128911706114081 | C10: 入账 | D10: 170.05 | E10: 聚合账户 | F10: 货款结算入账 | G10: 小店自卖 | H10: '6950146457801266618 | I10: '6950146457801266618 | J10: 'SS76006023018314348040058 | K10: 46043.687 | L10: '3787311554958066065 | M10: 【小火山】雪中飞儿童羽绒服冬装外套保暖冬装X2501326322FXT | P10: 普通订单 | Q10: 159 | R10: =Q10+SUM(T10:AC10) -> 179 | S10: 0 | T10: 0 | U10: 20 | V10: 0 | W10: 0 | X10: 0 | Y10: 0 | Z10: 0 | AA10: 0 | AB10: 0 | AC10: 0 | AD10: -8.95 | AE10: 0 | AF10: 0 | AG10: 0 | AH10: 0 | AI10: 0 | AJ10: 0 | AL10: 0 | AM10: 订单结算
A11: 46054.174 | B11: '2026020104103209737997264081 | C11: 入账 | D11: 170.05 | E11: 聚合账户 | F11: 货款结算入账 | G11: 小店自卖 | H11: '6950127036689684441 | I11: '6950127036689684441 | J11: 'SS75988987804245734860034 | K11: 46043.854 | L11: '3787311554958066065 | M11: 【小火山】雪中飞儿童羽绒服冬装外套保暖冬装X2501326322FXT | P11: 普通订单 | Q11: 179 | R11: =Q11+SUM(T11:AC11) -> 179 | S11: 0 | T11: 0 | U11: 0 | V11: 0 | W11: 0 | X11: 0 | Y11: 0 | Z11: 0 | AA11: 0 | AB11: 0 | AC11: 0 | AD11: -8.95 | AE11: 0 | AF11: 0 | AG11: 0 | AH11: 0 | AI11: 0 | AJ11: 0 | AL11: 0 | AM11: 订单结算
A12: 46054.174 | B12: '2026020104103038811244024081 | C12: 入账 | D12: 66.4 | E12: 聚合账户 | F12: 货款结算入账 | G12: 小店自卖 | H12: '6950144136995607613 | I12: '6950144136995607613 | J12: 'SS76005883611909166480009 | K12: 46043.742 | L12: '3780871747608379667 | M12: 雪中飞运动冬季男女童松紧带休闲裤直筒运动裤X2509329934FXT | P12: 普通订单 | Q12: 69.9 | R12: =Q12+SUM(T12:AC12) -> 69.9 | S12: 0 | T12: 0 | U12: 0 | V12: 0 | W12: 0 | X12: 0 | Y12: 0 | Z12: 0 | AA12: 0 | AB12: 0 | AC12: 0 | AD12: -3.5 | AE12: 0 | AF12: 0 | AG12: 0 | AH12: 0 | AI12: 0 | AJ12: 0 | AL12: 0 | AM12: 订单结算
A13: 46054.174 | B13: '2026020104103210327493184081 | C13: 入账 | D13: 170.05 | E13: 聚合账户 | F13: 货款结算入账 | G13: 巨量千川 | H13: '6923799515845328002 | I13: '6923799515845328002 | J13: 'SS76007034098513021590148 | K13: 46044.54 | L13: '3787311554958066065 | M13: 【小火山】雪中飞儿童羽绒服冬装外套保暖冬装X2501326322FXT | P13: 普通订单 | Q13: 179 | R13: =Q13+SUM(T13:AC13) -> 179 | S13: 0 | T13: 0 | U13: 0 | V13: 0 | W13: 0 | X13: 0 | Y13: 0 | Z13: 0 | AA13: 0 | AB13: 0 | AC13: 0 | AD13: -8.95 | AE13: 0 | AF13: 0 | AG13: 0 | AH13: 0 | AI13: 0 | AJ13: 0 | AL13: 0 | AM13: 订单结算
... A46: 46054.366 | B46: '2026020108464713099830184081 | C46: 入账 | D46: 170.05 | E46: 聚合账户 | F46: 货款结算入账 | G46: 巨量千川 | H46: '6923789717752413593 | I46: '6923789717752413593 | J46: 'SS76006148693690949120041 | K46: 46043.898 | L46: '3787311554958066065 | M46: 【小火山】雪中飞儿童羽绒服冬装外套保暖冬装X2501326322FXT | P46: 普通订单 | Q46: 149 | R46: =Q46+SUM(T46:AC46) -> 179 | S46: 0 | T46: 0 | U46: 30 | V46: 0 | W46: 0 | X46: 0 | Y46: 0 | Z46: 0 | AA46: 0 | AB46: 0 | AC46: 0 | AD46: -8.95 | AE46: 0 | AF46: 0 | AG46: 0 | AH46: 0 | AI46: 0 | AJ46: 0 | AL46: 0 | AM46: 订单结算
A47: 46054.367 | B47: '2026020108483823615616194081 | C47: 出账 | D47: 22.86 | E47: 聚合账户 | F47: 权益保险 | P47: 普通订单 | Q47: 0 | R47: =Q47+SUM(T47:AC47) -> 0 | S47: 0 | T47: 0 | U47: 0 | V47: 0 | W47: 0 | X47: 0 | Y47: 0 | Z47: 0 | AA47: 0 | AB47: 0 | AC47: 0 | AD47: 0 | AE47: 0 | AF47: 0 | AG47: 0 | AH47: 0 | AI47: 0 | AJ47: 0 | AL47: 0 | AM47: 保费扣除（6笔保单扣费,明细详见保费扣除明细）
A48: 46054.368 | B48: '2026020108492827897530974081 | C48: 入账 | D48: 170.05 | E48: 聚合账户 | F48: 货款结算入账 | G48: 小店自卖 | H48: '6923788906860740332 | I48: '6923788906860740332 | J48: 'SS76006021674222231230234 | K48: 46043.695 | L48: '3787311554958066065 | M48: 【小火山】雪中飞儿童羽绒服冬装外套保暖冬装X2501326322FXT | P48: 普通订单 | Q48: 179 | R48: =Q48+SUM(T48:AC48) -> 179 | S48: 0 | T48: 0 | U48: 0 | V48: 0 | W48: 0 | X48: 0 | Y48: 0 | Z48: 0 | AA48: 0 | AB48: 0 | AC48: 0 | AD48: -8.95 | AE48: 0 | AF48: 0 | AG48: 0 | AH48: 0 | AI48: 0 | AJ48: 0 | AL48: 0 | AM48: 订单结算
A49: 46054.369 | B49: '2026020108515903528133664081 | C49: 出账 | D49: 41.91 | E49: 聚合账户 | F49: 权益保险 | P49: 普通订单 | Q49: 0 | R49: =Q49+SUM(T49:AC49) -> 0 | S49: 0 | T49: 0 | U49: 0 | V49: 0 | W49: 0 | X49: 0 | Y49: 0 | Z49: 0 | AA49: 0 | AB49: 0 | AC49: 0 | AD49: 0 | AE49: 0 | AF49: 0 | AG49: 0 | AH49: 0 | AI49: 0 | AJ49: 0 | AL49: 0 | AM49: 保费扣除（11笔保单扣费,明细详见保费扣除明细）
A50: 46054.374 | B50: '2026020108574713056740384081 | C50: 出账 | D50: 83.82 | E50: 聚合账户 | F50: 权益保险 | P50: 普通订单 | Q50: 0 | R50: =Q50+SUM(T50:AC50) -> 0 | S50: 0 | T50: 0 | U50: 0 | V50: 0 | W50: 0 | X50: 0 | Y50: 0 | Z50: 0 | AA50: 0 | AB50: 0 | AC50: 0 | AD50: 0 | AE50: 0 | AF50: 0 | AG50: 0 | AH50: 0 | AI50: 0 | AJ50: 0 | AL50: 0 | AM50: 保费扣除（22笔保单扣费,明细详见保费扣除明细）
A51: 46054.375 | B51: '2026020108591505691684244081 | C51: 入账 | D51: 170.05 | E51: 聚合账户 | F51: 货款结算入账 | G51: 小店自卖 | H51: '6950144687867631409 | I51: '6950144687867631409 | J51: 'SS76006637625213793470131 | K51: 46043.905 | L51: '3787311554958066065 | M51: 【小火山】雪中飞儿童羽绒服冬装外套保暖冬装X2501326322FXT | P51: 普通订单 | Q51: 179 | R51: =Q51+SUM(T51:AC51) -> 179 | S51: 0 | T51: 0 | U51: 0 | V51: 0 | W51: 0 | X51: 0 | Y51: 0 | Z51: 0 | AA51: 0 | AB51: 0 | AC51: 0 | AD51: -8.95 | AE51: 0 | AF51: 0 | AG51: 0 | AH51: 0 | AI51: 0 | AJ51: 0 | AL51: 0 | AM51: 订单结算
A52: 46054.375 | B52: '2026020109003026230175064081 | C52: 入账 | D52: 170.05 | E52: 聚合账户 | F52: 货款结算入账 | G52: 小店自卖 | H52: '6923799730393349772 | I52: '6923799730393349772 | J52: 'SS76007076490467292500168 | K52: 46044.605 | L52: '3787311554958066065 | M52: 【小火山】雪中飞儿童羽绒服冬装外套保暖冬装X2501326322FXT | P52: 普通订单 | Q52: 157 | R52: =Q52+SUM(T52:AC52) -> 179 | S52: 0 | T52: 0 | U52: 22 | V52: 0 | W52: 0 | X52: 0 | Y52: 0 | Z52: 0 | AA52: 0 | AB52: 0 | AC52: 0 | AD52: -8.95 | AE52: 0 | AF52: 0 | AG52: 0 | AH52: 0 | AI52: 0 | AJ52: 0 | AL52: 0 | AM52: 订单结算
A53: 46054.376 | B53: '2026020109014438187382174081 | C53: 入账 | D53: 170.05 | E53: 聚合账户 | F53: 货款结算入账 | G53: 巨量千川 | H53: '6950222987647325297 | I53: '6950222987647325297 | J53: 'SS76007661157975662600080 | K53: 46046.79 | L53: '3787311554958066065 | M53: 【小火山】雪中飞儿童羽绒服冬装外套保暖冬装X2501326322FXT | P53: 普通订单 | Q53: 179 | R53: =Q53+SUM(T53:AC53) -> 179 | S53: 0 | T53: 0 | U53: 0 | V53: 0 | W53: 0 | X53: 0 | Y53: 0 | Z53: 0 | AA53: 0 | AB53: 0 | AC53: 0 | AD53: -8.95 | AE53: 0 | AF53: 0 | AG53: 0 | AH53: 0 | AI53: 0 | AJ53: 0 | AL53: 0 | AM53: 订单结算
A54: 46054.376 | B54: '2026020109014526472167034081 | C54: 入账 | D54: 170.05 | E54: 聚合账户 | F54: 货款结算入账 | G54: 小店自卖 | H54: '6923912871185054953 | I54: '6923912871185054953 | J54: 'SS76007393266327391120092 | K54: 46048.709 | L54: '3787311554958066065 | M54: 【小火山】雪中飞儿童羽绒服冬装外套保暖冬装X2501326322FXT | P54: 普通订单 | Q54: 159 | R54: =Q54+SUM(T54:AC54) -> 179 | S54: 0 | T54: 0 | U54: 20 | V54: 0 | W54: 0 | X54: 0 | Y54: 0 | Z54: 0 | AA54: 0 | AB54: 0 | AC54: 0 | AD54: -8.95 | AE54: 0 | AF54: 0 | AG54: 0 | AH54: 0 | AI54: 0 | AJ54: 0 | AL54: 0 | AM54: 订单结算
A55: 46054.377 | B55: '2026020109022229868362624081 | C55: 出账 | D55: 110.53 | E55: 聚合账户 | F55: 权益保险 | P55: 普通订单 | Q55: 0 | R55: =Q55+SUM(T55:AC55) -> 0 | S55: 0 | T55: 0 | U55: 0 | V55: 0 | W55: 0 | X55: 0 | Y55: 0 | Z55: 0 | AA55: 0 | AB55: 0 | AC55: 0 | AD55: 0 | AE55: 0 | AF55: 0 | AG55: 0 | AH55: 0 | AI55: 0 | AJ55: 0 | AL55: 0 | AM55: 保费扣除（29笔保单扣费,明细详见保费扣除明细）
A56: 46054.38 | B56: '2026020109070726386931564081 | C56: 入账 | D56: 170.05 | E56: 聚合账户 | F56: 货款结算入账 | G56: 巨量千川 | H56: '6950133795404059748 | I56: '6950133795404059748 | J56: 'SS76005923880551555080171 | K56: 46043.904 | L56: '3787311554958066065 | M56: 【小火山】雪中飞儿童羽绒服冬装外套保暖冬装X2501326322FXT | P56: 普通订单 | Q56: 179 | R56: =Q56+SUM(T56:AC56) -> 179 | S56: 0 | T56: 0 | U56: 0 | V56: 0 | W56: 0 | X56: 0 | Y56: 0 | Z56: 0 | AA56: 0 | AB56: 0 | AC56: 0 | AD56: -8.95 | AE56: 0 | AF56: 0 | AG56: 0 | AH56: 0 | AI56: 0 | AJ56: 0 | AL56: 0 | AM56: 订单结算
A57: 46054.384 | B57: '2026020109133229780707994081 | C57: 入账 | D57: 340.1 | E57: 聚合账户 | F57: 货款结算入账 | G57: 巨量千川 | H57: '6950131334658135954 | I57: '6950131334658135954 | J57: 'SS76006115132255936000047 | K57: 46043.791 | L57: '3787311554958066065 | M57: 【小火山】雪中飞儿童羽绒服冬装外套保暖冬装X2501326322FXT | P57: 普通订单 | Q57: 358 | R57: =Q57+SUM(T57:AC57) -> 358 | S57: 0 | T57: 0 | U57: 0 | V57: 0 | W57: 0 | X57: 0 | Y57: 0 | Z57: 0 | AA57: 0 | AB57: 0 | AC57: 0 | AD57: -17.9 | AE57: 0 | AF57: 0 | AG57: 0 | AH57: 0 | AI57: 0 | AJ57: 0 | AL57: 0 | AM57: 订单结算
A58: 46054.385 | B58: '2026020109135021712123344081 | C58: 出账 | D58: 26.67 | E58: 聚合账户 | F58: 权益保险 | P58: 普通订单 | Q58: 0 | R58: =Q58+SUM(T58:AC58) -> 0 | S58: 0 | T58: 0 | U58: 0 | V58: 0 | W58: 0 | X58: 0 | Y58: 0 | Z58: 0 | AA58: 0 | AB58: 0 | AC58: 0 | AD58: 0 | AE58: 0 | AF58: 0 | AG58: 0 | AH58: 0 | AI58: 0 | AJ58: 0 | AL58: 0 | AM58: 保费扣除（7笔保单扣费,明细详见保费扣除明细）
A59: 46054.385 | B59: '2026020109135327726157204081 | C59: 入账 | D59: 170.05 | E59: 聚合账户 | F59: 货款结算入账 | G59: 小店自卖 | H59: '6950154462153742086 | I59: '6950154462153742086 | J59: 'SS76006607469052441950098 | K59: 46044.44 | L59: '3787311554958066065 | M59: 【小火山】雪中飞儿童羽绒服冬装外套保暖冬装X2501326322FXT | P59: 普通订单 | Q59: 159 | R59: =Q59+SUM(T59:AC59) -> 179 | S59: 0 | T59: 0 | U59: 20 | V59: 0 | W59: 0 | X59: 0 | Y59: 0 | Z59: 0 | AA59: 0 | AB59: 0 | AC59: 0 | AD59: -8.95 | AE59: 0 | AF59: 0 | AG59: 0 | AH59: 0 | AI59: 0 | AJ59: 0 | AL59: 0 | AM59: 订单结算
A60: 46054.387 | B60: '2026020109173306125161594081 | C60: 出账 | D60: 64.77 | E60: 聚合账户 | F60: 权益保险 | P60: 普通订单 | Q60: 0 | R60: =Q60+SUM(T60:AC60) -> 0 | S60: 0 | T60: 0 | U60: 0 | V60: 0 | W60: 0 | X60: 0 | Y60: 0 | Z60: 0 | AA60: 0 | AB60: 0 | AC60: 0 | AD60: 0 | AE60: 0 | AF60: 0 | AG60: 0 | AH60: 0 | AI60: 0 | AJ60: 0 | AL60: 0 | AM60: 保费扣除（17笔保单扣费,明细详见保费扣除明细）
A61: 46054.391 | B61: '2026020109223404539520274081 | C61: 出账 | D61: 3.81 | E61: 聚合账户 | F61: 权益保险 | P61: 普通订单 | Q61: 0 | R61: =Q61+SUM(T61:AC61) -> 0 | S61: 0 | T61: 0 | U61: 0 | V61: 0 | W61: 0 | X61: 0 | Y61: 0 | Z61: 0 | AA61: 0 | AB61: 0 | AC61: 0 | AD61: 0 | AE61: 0 | AF61: 0 | AG61: 0 | AH61: 0 | AI61: 0 | AJ61: 0 | AL61: 0 | AM61: 保费扣除（1笔保单扣费,明细详见保费扣除明细）
A62: 46054.395 | B62: '2026020109281326175452704081 | C62: 出账 | D62: 11.43 | E62: 聚合账户 | F62: 权益保险 | P62: 普通订单 | Q62: 0 | R62: =Q62+SUM(T62:AC62) -> 0 | S62: 0 | T62: 0 | U62: 0 | V62: 0 | W62: 0 | X62: 0 | Y62: 0 | Z62: 0 | AA62: 0 | AB62: 0 | AC62: 0 | AD62: 0 | AE62: 0 | AF62: 0 | AG62: 0 | AH62: 0 | AI62: 0 | AJ62: 0 | AL62: 0 | AM62: 保费扣除（3笔保单扣费,明细详见保费扣除明细）
A63: 46054.399 | B63: '2026020109342537972549394081 | C63: 出账 | D63: 15.24 | E63: 聚合账户 | F63: 权益保险 | P63: 普通订单 | Q63: 0 | R63: =Q63+SUM(T63:AC63) -> 0 | S63: 0 | T63: 0 | U63: 0 | V63: 0 | W63: 0 | X63: 0 | Y63: 0 | Z63: 0 | AA63: 0 | AB63: 0 | AC63: 0 | AD63: 0 | AE63: 0 | AF63: 0 | AG63: 0 | AH63: 0 | AI63: 0 | AJ63: 0 | AL63: 0 | AM63: 保费扣除（4笔保单扣费,明细详见保费扣除明细）
A64: 46054.4 | B64: '2026020109355515334159744081 | C64: 入账 | D64: 170.05 | E64: 聚合账户 | F64: 货款结算入账 | G64: 巨量千川 | H64: '6950142026667857878 | I64: '6950142026667857878 | J64: 'SS76006028566273233980180 | K64: 46043.731 | L64: '3779048132244013371 | M64: 【升级款】雪中飞亲子儿童连帽羽绒服秋冬加厚外套X2501326322FXT | P64: 普通订单 | Q64: 179 | R64: =Q64+SUM(T64:AC64) -> 179 | S64: 0 | T64: 0 | U64: 0 | V64: 0 | W64: 0 | X64: 0 | Y64: 0 | Z64: 0 | AA64: 0 | AB64: 0 | AC64: 0 | AD64: -8.95 | AE64: 0 | AF64: 0 | AG64: 0 | AH64: 0 | AI64: 0 | AJ64: 0 | AL64: 0 | AM64: 订单结算
A65: 46054.403 | B65: '2026020109393606473324024081 | C65: 出账 | D65: 15.24 | E65: 聚合账户 | F65: 权益保险 | P65: 普通订单 | Q65: 0 | R65: =Q65+SUM(T65:AC65) -> 0 | S65: 0 | T65: 0 | U65: 0 | V65: 0 | W65: 0 | X65: 0 | Y65: 0 | Z65: 0 | AA65: 0 | AB65: 0 | AC65: 0 | AD65: 0 | AE65: 0 | AF65: 0 | AG65: 0 | AH65: 0 | AI65: 0 | AJ65: 0 | AL65: 0 | AM65: 保费扣除（4笔保单扣费,明细详见保费扣除明细）
A66: 46054.403 | B66: '2026020109401036960220594081 | C66: 入账 | D66: 170.05 | E66: 聚合账户 | F66: 货款结算入账 | G66: 巨量千川 | H66: '6923814437093408339 | I66: '6923814437093408339 | J66: 'SS75999834784197353470029 | K66: 46044.458 | L66: '3787311554958066065 | M66: 【小火山】雪中飞儿童羽绒服冬装外套保暖冬装X2501326322FXT | P66: 普通订单 | Q66: 159 | R66: =Q66+SUM(T66:AC66) -> 179 | S66: 0 | T66: 0 | U66: 20 | V66: 0 | W66: 0 | X66: 0 | Y66: 0 | Z66: 0 | AA66: 0 | AB66: 0 | AC66: 0 | AD66: -8.95 | AE66: 0 | AF66: 0 | AG66: 0 | AH66: 0 | AI66: 0 | AJ66: 0 | AL66: 0 | AM66: 订单结算
A67: 46054.403 | B67: '2026020109401433933276584081 | C67: 入账 | D67: 170.05 | E67: 聚合账户 | F67: 货款结算入账 | G67: 巨量千川 | H67: '6923808667715402752 | I67: '6923808667715402752 | J67: 'SS76007076616169231630137 | K67: 46044.603 | L67: '3787311554958066065 | M67: 【小火山】雪中飞儿童羽绒服冬装外套保暖冬装X2501326322FXT | P67: 普通订单 | Q67: 159 | R67: =Q67+SUM(T67:AC67) -> 179 | S67: 0 | T67: 0 | U67: 20 | V67: 0 | W67: 0 | X67: 0 | Y67: 0 | Z67: 0 | AA67: 0 | AB67: 0 | AC67: 0 | AD67: -8.95 | AE67: 0 | AF67: 0 | AG67: 0 | AH67: 0 | AI67: 0 | AJ67: 0 | AL67: 0 | AM67: 订单结算
A68: 46054.404 | B68: '2026020109414032974484894081 | C68: 出账 | D68: 3.81 | E68: 聚合账户 | F68: 权益保险 | P68: 普通订单 | Q68: 0 | R68: =Q68+SUM(T68:AC68) -> 0 | S68: 0 | T68: 0 | U68: 0 | V68: 0 | W68: 0 | X68: 0 | Y68: 0 | Z68: 0 | AA68: 0 | AB68: 0 | AC68: 0 | AD68: 0 | AE68: 0 | AF68: 0 | AG68: 0 | AH68: 0 | AI68: 0 | AJ68: 0 | AL68: 0 | AM68: 保费扣除（1笔保单扣费,明细详见保费扣除明细）
A69: 46054.406 | B69: '2026020109445916618622074081 | C69: 入账 | D69: 170.05 | E69: 聚合账户 | F69: 货款结算入账 | G69: 小店自卖 | H69: '6950140312541206208 | I69: '6950140312541206208 | J69: 'SS76006245325042161050090 | K69: 46043.806 | L69: '3787311554958066065 | M69: 【小火山】雪中飞儿童羽绒服冬装外套保暖冬装X2501326322FXT | P69: 普通订单 | Q69: 159 | R69: =Q69+SUM(T69:AC69) -> 179 | S69: 0 | T69: 0 | U69: 20 | V69: 0 | W69: 0 | X69: 0 | Y69: 0 | Z69: 0 | AA69: 0 | AB69: 0 | AC69: 0 | AD69: -8.95 | AE69: 0 | AF69: 0 | AG69: 0 | AH69: 0 | AI69: 0 | AJ69: 0 | AL69: 0 | AM69: 订单结算
A70: 46054.407 | B70: '2026020109452802487587944081 | C70: 入账 | D70: 170.05 | E70: 聚合账户 | F70: 货款结算入账 | G70: 巨量千川 | H70: '6923792997693357699 | I70: '6923792997693357699 | J70: 'SS76005791226157473800081 | K70: 46043.746 | L70: '3787311554958066065 | M70: 【小火山】雪中飞儿童羽绒服冬装外套保暖冬装X2501326322FXT | P70: 普通订单 | Q70: 159 | R70: =Q70+SUM(T70:AC70) -> 179 | S70: 0 | T70: 0 | U70: 20 | V70: 0 | W70: 0 | X70: 0 | Y70: 0 | Z70: 0 | AA70: 0 | AB70: 0 | AC70: 0 | AD70: -8.95 | AE70: 0 | AF70: 0 | AG70: 0 | AH70: 0 | AI70: 0 | AJ70: 0 | AL70: 0 | AM70: 订单结算
A71: 46054.408 | B71: '2026020109465434444249754081 | C71: 入账 | D71: 170.05 | E71: 聚合账户 | F71: 货款结算入账 | G71: 小店自卖 | H71: '6950154459920143427 | I71: '6950154459920143427 | J71: 'SS76006251940912663540127 | K71: 46044.437 | L71: '3787311554958066065 | M71: 【小火山】雪中飞儿童羽绒服冬装外套保暖冬装X2501326322FXT | P71: 普通订单 | Q71: 159 | R71: =Q71+SUM(T71:AC71) -> 179 | S71: 0 | T71: 0 | U71: 20 | V71: 0 | W71: 0 | X71: 0 | Y71: 0 | Z71: 0 | AA71: 0 | AB71: 0 | AC71: 0 | AD71: -8.95 | AE71: 0 | AF71: 0 | AG71: 0 | AH71: 0 | AI71: 0 | AJ71: 0 | AL71: 0 | AM71: 订单结算
A72: 46054.408 | B72: '2026020109465225086533534081 | C72: 入账 | D72: 159.35 | E72: 聚合账户 | F72: 货款结算入账 | G72: 巨量千川 | H72: '6923785819948612970 | I72: '6923785819948612970 | J72: 'SS75988564273186081540026 | K72: 46043.956 | L72: '3787311554958066065 | M72: 【小火山】雪中飞儿童羽绒服冬装外套保暖冬装X2501326322FXT | P72: 普通订单 | Q72: 159 | R72: =Q72+SUM(T72:AC72) -> 167.74 | S72: 0 | T72: 0 | U72: 18.74 | V72: 0 | W72: 0 | X72: 0 | Y72: 0 | Z72: 0 | AA72: 0 | AB72: 0 | AC72: -10 | AD72: -8.39 | AE72: 0 | AF72: 0 | AG72: 0 | AH72: 0 | AI72: 0 | AJ72: 0 | AL72: 0 | AM72: 订单结算
...

Sheet 已核对收入
A1: 原始线上订单号 | B1: 求和项:金额
A2: 6923416114502532384 | B2: -169
A3: 6923455763794263484 | B3: -179
A4: 6923636505633586984 | B4: 179
A5: 6923640314699284416 | B5: -179
A6: 6923643815047822963 | B6: 179
A7: 6923652229969313434 | B7: -179
A8: 6923661839766748780 | B8: -179
A9: 6923667343994027127 | B9: -20.27
A10: 6923676186043579878 | B10: 179
A11: 6923691053209255280 | B11: -179
A12: 6923706623434718909 | B12: 199
A13: 6923706884902846404 | B13: 179
... A2489: 总计 | B2489: 438770.18

Sheet 销售汇总
A3: 款式编码 | B3: 求和项:件数 | C3: 求和项:金额
A4: X2501319062FXT | B4: 1 | C4: 199
A5: X2501319626FXT | B5: 2 | C5: 358
A6: X2501324376FXT | B6: 1 | C6: 179
A7: X2501326322FXT | B7: 2280 | C7: 407489.64
A8: X250138238FXT | B8: 54 | C8: 10673.74
A9: X250138240FXT | B9: 32 | C9: 5088
A10: X250138648FXT | B10: 24 | C10: 4296
A11: X250138650FXT | B11: 1 | C11: 199
A12: X2501419056FT | B12: 2 | C12: 518
A13: X2501419060FXT | B13: 2 | C13: 558
A14: X2501419066FXT | B14: 3 | C14: 837
A15: X2501419131FT | B15: 1 | C15: 299
... A31: X40144476FXT | B31: 1 | C31: 259
A32: (空白)
A33: 总计 | B33: 2482 | C33: 438770.18

Sheet 聚水潭导出店铺数据
A1: 内部订单号 | B1: 标记多标签 | C1: 售后单号 | D1: 订单类型 | E1: 线上订单号 | F1: 平台外部订单号 | G1: 订单状态 | H1: 发货仓 | I1: 虚拟仓 | J1: 分销商 | K1: 店铺 | L1: 买家账号 | M1: 买家ID | N1: 买家留言 | O1: 卖家备注 | P1: 订单日期 | Q1: 发货日期 | R1: 付款日期 | S1: 确认收货日期 | T1: 供销支付时间 | U1: 省 | V1: 市 | W1: 区县 | X1: 订单快递公司 | Y1: 订单快递单号 | Z1: 售后快递公司 | AA1: 售后快递单号 | AB1: 收货人 | AC1: 售后登记日期 | AD1: 售后确认日期 | AE1: 售后进仓日期 | AF1: 售后进仓单号 | AG1: 收货仓 | AH1: 售后分类 | AI1: 问题类型 | AJ1: 商品编码 | AK1: 店铺款式编码 | AL1: 原始线上订单号 | AM1: 款式编码 | AN1: 产品分类 | AO1: 虚拟分类 | AP1: 商品简称 | AQ1: 颜色规格 | AR1: 线上颜色规格 | AS1: 品牌 | AT1: 供应商 | AU1: 供应商款号 | AV1: 供应商商品编码 | AW1: 商品标签 | AX1: 组合装实体编码 | AY1: 基本售价 | AZ1: 成本价 | BA1: 成本价来源 | BB1: 销售数量 | BC1: 赠品数量 | BD1: 实发数量 | BE1: 实发金额 | BF1: 销售金额 | BG1: 销售成本 | BH1: 实发成本 | BI1: 销售毛利 | BJ1: 销售毛利率 | BK1: 已付金额 | BL1: 应付金额 | BM1: 售价 | BN1: 基本金额 | BO1: 当期退货数量 | BP1: 当期实退数量 | BQ1: 当期退货金额 | BR1: 当期退货成本 | BS1: 当期实退成本 | BT1: 当期实退金额 | BU1: 运费收入 | BV1: 运费收入分摊 | BW1: 运费支出 | BX1: 运费支出分摊 | BY1: 优惠金额 | BZ1: 订单重量 | CA1: 订单商品重量 | CB1: 商店站点 | CC1: 订单来源 | CD1: 便签 | CE1: 其它价格1 | CF1: 件数 | CG1: 金额 | CH1: 抖音资金账单金额
A2: 19675024 | B2: 优先发货,发货后售后,小店,店铺新客,抖音,高频购买 | D2: 普通订单 | E2: 6923455763794263484 | G2: 已发货 | H2: 河北贝吉实业集团有限公司 | K2: 抖音-雪中飞德煌童装专卖店 | L2: 1@#GWBmmHWFl9twJLEV8t1WG+mzxE4ul4+7udBQ0AiGV/9GIpbUNQSA8y5iSDBr7Sqt99Ec | M2: 12867611 | O2: (收) 颜色分类:蝶恋紫;尺码大小:170cmI568114919700*1# | P2: 2026/1/6 16:23:14 | Q2: 2026/1/7 10:11:43 | R2: 2026/1/6 16:23:25 | S2: 2026/1/14 10:11:48 | T2: 2026/1/6 16:23:25 | U2: 湖北省 | V2: 荆州市 | W2: 监利市 | X2: 圆通速递 | Y2: YT0003734281957 | AB2: 147:颜* | AJ2: I568150074600 | AK2: 3787311554958066065 | AL2: 6923455763794263484 | AM2: X2501326322FXT | AP2: 儿童轻薄羽绒服 | AQ2: 绯红;160 | AR2: 颜色分类:绯红;尺码大小:160CM | AS2: 雪中飞 | AT2: 无唛尚品 | AY2: 179 | AZ2: 90 | BA2: 普通商品资料成本价 | BB2: 1 | BD2: 1 | BE2: 179 | BF2: 179 | BG2: 90 | BH2: 90 | BI2: 89 | BJ2: 49.721% | BM2: 179 | BN2: 179 | BX2: 2.8 | CB2: 头条放心购 | CC2: TOUTIAOFXG | CE2: 101.5 | CF2: 0 | CG2: 0 | CH2: =_xlfn.XLOOKUP(AL2,抖音账单汇总!$A:$A,抖音账单汇总!$B:$B) -> -179
A3: 21084099 | B3: 小店,平台补贴,店铺老客,服务优先,高频购买 | D3: 普通订单 | E3: 6950766742891665321 | G3: 已发货 | H3: 河北贝吉实业集团有限公司 | K3: 抖音-雪中飞德煌童装专卖店 | L3: 1@#z3Bl7h2mItj2my4HO6B1jh5TO7drsyUtmTMONWT40u5oP06Zq8MV7NT/mYrcwEfZ+wBk | M3: 13896512 | P3: 2026/2/18 14:18:05 | Q3: 2026/2/18 17:07:25 | R3: 2026/2/18 14:18:12 | S3: 2026/2/23 21:45:27 | T3: 2026/2/18 14:18:12 | U3: 河南省 | V3: 郑州市 | W3: 新郑市 | X3: 京东快递 | Y3: JDAZ23866283026 | AB3: 147:连* | AJ3: H626415547302 | AK3: 3787311554958066065 | AL3: 6950766742891665321 | AM3: X250138238FXT | AN3: 轻薄羽绒服 | AP3: 儿童轻薄羽绒服 | AQ3: 藏青色;130 | AR3: 颜色分类:藏青（8238款）;尺码大小:130CM | AS3: 雪中飞 | AT3: 茸淳羽绒 | AW3: 每日加权 | AY3: 199 | AZ3: 105.3 | BA3: 普通商品资料成本价 | BB3: 1 | BD3: 1 | BE3: 199 | BF3: 199 | BG3: 105.3 | BH3: 105.3 | BI3: 93.7 | BJ3: 47.085% | BK3: 199 | BL3: 199 | BM3: 199 | BN3: 199 | BU3: 0 | BW3: 15 | BX3: 15 | BZ3: 0.512 | CA3: 0.512 | CB3: 头条放心购 | CC3: TOUTIAOFXG | CE3: 116.8 | CF3: =BD3-BP3 -> 1 | CG3: 199 | CH3: =_xlfn.XLOOKUP(AL3,抖音账单汇总!$A:$A,抖音账单汇总!$B:$B) -> 199
A4: 21081483 | B4: 发货后售后,小店,店铺新客,抖音,高频购买 | D4: 普通订单 | E4: 6924387514871283172 | G4: 已发货 | H4: 河北贝吉实业集团有限公司 | K4: 抖音-雪中飞德煌童装专卖店 | L4: 1@#kJAIYJrStILJaLum1t2WfTmTWnqv0C3MlW+8EQK5t+71DkI9RoUSEjMVw/j4EXcvnkBc | M4: 13894338 | O4: hp返8【雪風 02-26 15:27】 | P4: 2026/2/16 17:49:57 | Q4: 2026/2/18 13:52:41 | R4: 2026/2/16 17:50:03 | S4: 2026/2/25 13:52:43 | T4: 2026/2/16 17:50:03 | U4: 湖南省 | V4: 长沙市 | W4: 浏阳市 | X4: 京东快递 | Y4: JDAZ23864881536 | AB4: 147:张* | AJ4: I568150018600 | AK4: 3787311554958066065 | AL4: 6924387514871283172 | AM4: X2501326322FXT | AP4: 儿童轻薄羽绒服 | AQ4: 橄榄绿;160 | AR4: 颜色分类:橄榄绿;尺码大小:160CM | AS4: 雪中飞 | AT4: 涛源 | AY4: 179 | AZ4: 86.7 | BA4: 普通商品资料成本价 | BB4: 1 | BD4: 1 | BE4: 179 | BF4: 179 | BG4: 86.7 | BH4: 86.7 | BI4: 92.3 | BJ4: 51.564% | BK4: 179 | BL4: 179 | BM4: 179 | BN4: 179 | BU4: 0 | BW4: 15 | BX4: 15 | BZ4: 0.506 | CA4: 0.506 | CB4: 头条放心购 | CC4: TOUTIAOFXG | CE4: 98.2 | CF4: =BD4-BP4 -> 1 | CG4: 171 | CH4: =_xlfn.XLOOKUP(AL4,抖音账单汇总!$A:$A,抖音账单汇总!$B:$B) -> 171
A5: 19675024 | B5: 优先发货,发货后售后,小店,店铺新客,抖音,高频购买 | C5: 1226353186 | D5: 普通订单 | E5: 6923455763794263484 | G5: 已发货 | H5: 河北贝吉实业集团有限公司 | K5: 抖音-雪中飞德煌童装专卖店 | L5: 1@#GWBmmHWFl9twJLEV8t1WG+mzxE4ul4+7udBQ0AiGV/9GIpbUNQSA8y5iSDBr7Sqt99Ec | M5: 12867611 | O5: (收) 颜色分类:蝶恋紫;尺码大小:170cmI568114919700*1# | P5: 2026/1/6 16:23:14 | Q5: 2026/1/7 10:11:43 | R5: 2026/1/6 16:23:25 | S5: 2026/1/14 10:11:48 | T5: 2026/1/6 16:23:25 | U5: 湖北省 | V5: 荆州市 | W5: 监利市 | X5: 圆通速递 | Y5: YT0003734281957 | Z5: 韵达快递 | AA5: 312955322570264 | AB5: 147:颜* | AC5: 2026/2/4 19:18:58 | AD5: 2026/2/7 14:28:20 | AE5: 2026-02-07 14:28:13 | AF5: 20171187 | AG5: 河北贝吉实业集团有限公司 | AH5: 普通退货 | AI5: 与商家协商一致退款 | AJ5: I568114919700 | AK5: 3787311554958066065 | AL5: 6923455763794263484 | AM5: X2501326322FXT | AN5: 轻薄羽绒服 | AP5: 儿童轻薄羽绒服 | AQ5: 香芋紫;170 | AR5: 颜色分类:蝶恋紫;尺码大小:170CM | AS5: 雪中飞 | AT5: 涛源 | AY5: 179 | AZ5: 86.7 | BA5: 普通商品资料成本价 | BB5: 1 | BD5: 1 | BE5: 179 | BF5: 179 | BG5: 86.7 | BH5: 86.7 | BI5: 92.3 | BJ5: 51.564% | BK5: 358 | BL5: 358 | BM5: 179 | BN5: 179 | BO5: 1 | BP5: 1 | BQ5: 179 | BR5: 86.7 | BS5: 86.7 | BT5: 179 | BU5: 0 | BW5: 5.6 | BX5: 2.8 | BZ5: 1.043 | CA5: 1.043 | CB5: 头条放心购 | CC5: TOUTIAOFXG | CE5: 98.2 | CF5: -1 | CG5: -179 | CH5: =_xlfn.XLOOKUP(AL5,抖音账单汇总!$A:$A,抖音账单汇总!$B:$B) -> -179
A6: 21078885 | B6: 小店,店铺老客,抖音,高频购买 | D6: 普通订单 | E6: 6950767968497244059 | G6: 已发货 | H6: 河北贝吉实业集团有限公司 | K6: 抖音-雪中飞德煌童装专卖店 | L6: 1@#vNwC0k86jojzwXHn09Ly/x6b1HWAlSLA+r1tbkmXTUvHLbGyDWXC22M0+5lu6bd5kUJ16iUCnA== | M6: 13883831 | P6: 2026/2/15 9:43:34 | Q6: 2026/2/15 13:15:18 | R6: 2026/2/15 9:43:35 | S6: 2026/2/22 13:15:20 | T6: 2026/2/15 9:43:35 | U6: 上海 | V6: 上海市 | W6: 浦东新区 | X6: 京东快递 | Y6: JDAZ23847075801 | AB6: 147:叶* | AJ6: H493814417140 | AK6: 3787311554958066065 | AL6: 6950767968497244059 | AM6: X250138240FXT | AN6: 羽绒服 | AP6: 儿童轻薄羽绒服 | AQ6: 黑色;150 | AR6: 颜色分类:黑色（8240款）;尺码大小:150CM | AS6: 雪中飞 | AT6: 茸淳羽绒 | AW6: 每日加权 | AY6: 179 | AZ6: 87 | BA6: 普通商品资料成本价 | BB6: 1 | BD6: 1 | BE6: 159 | BF6: 159 | BG6: 87 | BH6: 87 | BI6: 72 | BJ6: 45.283% | BK6: 159 | BL6: 159 | BM6: 159 | BN6: 159 | BU6: 0 | BW6: 15 | BX6: 15 | BZ6: 0.493 | CA6: 0.493 | CB6: 头条放心购 | CC6: TOUTIAOFXG | CE6: 98.5 | CF6: =BD6-BP6 -> 1 | CG6: 159 | CH6: =_xlfn.XLOOKUP(AL6,抖音账单汇总!$A:$A,抖音账单汇总!$B:$B) -> 159
A7: 20037758 | B7: 发货后售后,小店,平台补贴,店铺新客,抖音,极速发货,直播间 | C7: 1226246815 | D7: 普通订单 | E7: 6923640314699284416 | G7: 已发货 | H7: 河北贝吉实业集团有限公司 | K7: 抖音-雪中飞德煌童装专卖店 | L7: 1@#PrdAaJ/c19AB08ja780iU+2EKC4MlXBj6RwsFAEr5mTfsiLF9a0L8/Z6wV/i7YQwMlBANg== | M7: 13125723 | O7: cp8 ，14点红云,(收) 新雾蓝;170I568114898700*1# | P7: 2026/1/16 11:46:42 | Q7: 2026/1/16 14:07:46 | R7: 2026/1/16 11:46:55 | S7: 2026/1/23 14:07:48 | T7: 2026/1/16 11:46:55 | U7: 安徽省 | V7: 合肥市 | W7: 肥东县 | X7: 圆通速递 | Y7: YT0006530080771 | Z7: 中通快递 | AA7: 73594118093819 | AB7: 147:王* | AC7: 2026/1/30 16:29:14 | AD7: 2026/2/2 13:41:17 | AE7: 2026-02-02 13:41:06 | AF7: 20009694 | AG7: 河北贝吉实业集团有限公司 | AH7: 普通退货 | AI7: 多拍/错拍/不想要 | AJ7: I568114898140 | AK7: 3787311554958066065 | AL7: 6923640314699284416 | AM7: X2501326322FXT | AP7: 儿童轻薄羽绒服 | AQ7: 新雾蓝;150 | AR7: 颜色分类:新雾蓝;尺码大小:150CM | AS7: 雪中飞 | AT7: 涛源 | AY7: 179 | AZ7: 86.7 | BA7: 普通商品资料成本价 | BB7: 1 | BD7: 1 | BE7: 179 | BF7: 179 | BG7: 86.7 | BH7: 86.7 | BI7: 92.3 | BJ7: 51.564% | BK7: 179 | BL7: 179 | BM7: 179 | BN7: 179 | BO7: 1 | BQ7: 179 | BR7: 86.7 | BU7: 0 | BW7: 3.6 | BX7: 3.6 | BZ7: 0.481 | CA7: 0.481 | CB7: 头条放心购 | CC7: TOUTIAOFXG | CE7: 98.2 | CF7: -1 | CG7: -179 | CH7: =_xlfn.XLOOKUP(AL7,抖音账单汇总!$A:$A,抖音账单汇总!$B:$B) -> -179
A8: 21076980 | B8: 小店,平台补贴,店铺老客,抖音极速版,直播间,高频购买 | D8: 普通订单 | E8: 6950742490609031071 | G8: 已发货 | H8: 河北贝吉实业集团有限公司 | K8: 抖音-雪中飞德煌童装专卖店 | L8: 1@#usS1WUSpN8Gr+E3nz4vYl/ls6EyPfg5JGJdJ29emjx9c7t8LmLuzMSszNjg+9i2lOGrG | M8: 13866300 | P8: 2026/2/14 12:37:53 | Q8: 2026/2/14 15:59:08 | R8: 2026/2/14 12:38:02 | S8: 2026/2/21 15:59:10 | T8: 2026/2/14 12:38:02 | U8: 安徽省 | V8: 芜湖市 | W8: 弋江区 | X8: 京东快递 | Y8: JDAZ23838272891 | AB8: 147:鲍* | AJ8: I568150018700 | AK8: 3787311554958066065 | AL8: 6950742490609031071 | AM8: X2501326322FXT | AP8: 儿童轻薄羽绒服 | AQ8: 橄榄绿;170 | AR8: 颜色分类:橄榄绿;尺码大小:170CM | AS8: 雪中飞 | AT8: 涛源 | AY8: 179 | AZ8: 86.7 | BA8: 普通商品资料成本价 | BB8: 1 | BD8: 1 | BE8: 179 | BF8: 179 | BG8: 86.7 | BH8: 86.7 | BI8: 92.3 | BJ8: 51.564% | BK8: 179 | BL8: 179 | BM8: 179 | BN8: 179 | BU8: 0 | BW8: 15 | BX8: 15 | BZ8: 0.537 | CA8: 0.537 | CB8: 头条放心购 | CC8: TOUTIAOFXG | CE8: 98.2 | CF8: =BD8-BP8 -> 1 | CG8: 179 | CH8: =_xlfn.XLOOKUP(AL8,抖音账单汇总!$A:$A,抖音账单汇总!$B:$B) -> 179
A9: 20037758 | B9: 发货后售后,小店,平台补贴,店铺新客,抖音,极速发货,直播间 | C9: 1226246815 | D9: 普通订单 | E9: 6923640314699284416 | G9: 已发货 | H9: 河北贝吉实业集团有限公司 | K9: 抖音-雪中飞德煌童装专卖店 | L9: 1@#PrdAaJ/c19AB08ja780iU+2EKC4MlXBj6RwsFAEr5mTfsiLF9a0L8/Z6wV/i7YQwMlBANg== | O9: cp8 ，14点红云,(收) 新雾蓝;170I568114898700*1# | P9: 2026/1/16 11:46:42 | Q9: 2026/1/16 14:07:46 | R9: 2026/1/16 11:46:55 | U9: 安徽省 | V9: 合肥市 | W9: 肥东县 | X9: 圆通速递 | Y9: YT0006530080771 | Z9: 中通快递 | AA9: 73594118093819 | AB9: 147:王* | AC9: 2026/1/30 16:29:14 | AD9: 2026/2/2 13:41:17 | AE9: 2026-02-02 13:41:06 | AF9: 20009694 | AG9: 河北贝吉实业集团有限公司 | AH9: 普通退货 | AI9: 多拍/错拍/不想要 | AJ9: I568114898700 | AL9: 6923640314699284416 | AM9: X2501326322FXT | AP9: 儿童轻薄羽绒服 | AQ9: 新雾蓝;170 | AR9: 新雾蓝;170 | AS9: 雪中飞 | AT9: 涛源 | AY9: 179 | AZ9: 86.7 | BF9: 0 | BJ9: 0.000% | BP9: 1 | BS9: 86.7 | CB9: 头条放心购 | CE9: 98.2 | CF9: 0 | CG9: 0 | CH9: =_xlfn.XLOOKUP(AL9,抖音账单汇总!$A:$A,抖音账单汇总!$B:$B) -> -179
A10: 21070645 | B10: 小店,店铺新客,抖音,服务优先,高频购买 | D10: 普通订单 | E10: 6950728574875866280 | G10: 已发货 | H10: 河北贝吉实业集团有限公司 | K10: 抖音-雪中飞德煌童装专卖店 | L10: 1@#xprY5As0/CxBKVAfxt5eb4lnRFJ0GpmwEg6p3VoKFyRZ4XhZh2JxQClUz7LXq5qalHJox0WFldo= | M10: 13885768 | P10: 2026/2/13 3:57:17 | Q10: 2026/2/13 10:29:28 | R10: 2026/2/13 3:57:19 | S10: 2026/2/20 10:29:29 | T10: 2026/2/13 3:57:19 | U10: 重庆 | V10: 重庆市 | W10: 沙坪坝区 | X10: 京东快递 | Y10: JDAZ23813768295 | AB10: 147:唐* | AJ10: I568150018700 | AK10: 3779048132244013371 | AL10: 6950728574875866280 | AM10: X2501326322FXT | AP10: 儿童轻薄羽绒服 | AQ10: 橄榄绿;170 | AR10: 颜色分类:橄榄绿;尺码大小:170CM | AS10: 雪中飞 | AT10: 涛源 | AY10: 179 | AZ10: 86.7 | BA10: 普通商品资料成本价 | BB10: 1 | BD10: 1 | BE10: 179 | BF10: 179 | BG10: 86.7 | BH10: 86.7 | BI10: 92.3 | BJ10: 51.564% | BK10: 179 | BL10: 179 | BM10: 179 | BN10: 179 | BU10: 0 | BW10: 15 | BX10: 15 | BZ10: 0.537 | CA10: 0.537 | CB10: 头条放心购 | CC10: TOUTIAOFXG | CE10: 98.2 | CF10: =BD10-BP10 -> 1 | CG10: 179 | CH10: =_xlfn.XLOOKUP(AL10,抖音账单汇总!$A:$A,抖音账单汇总!$B:$B) -> 179
A11: 21070327 | B11: 小店,平台补贴,店铺新客,抖音,高频购买 | D11: 普通订单 | E11: 6924337955066903674 | G11: 已发货 | H11: 河北贝吉实业集团有限公司 | K11: 抖音-雪中飞德煌童装专卖店 | L11: 1@#2eYD5mOtYnQnwRgpwcEto09eBSrU/62fitXuSHze5rnewguX2BACXZ2+p/oqXHduA3YW | M11: 13850164 | P11: 2026/2/13 0:30:15 | Q11: 2026/2/13 10:11:06 | R11: 2026/2/13 0:30:30 | S11: 2026/2/20 10:11:11 | T11: 2026/2/13 0:30:30 | U11: 湖南省 | V11: 常德市 | W11: 鼎城区 | X11: 京东快递 | Y11: JDAZ23813829585 | AB11: 147:许* | AJ11: I568150018252 | AK11: 3779048132244013371 | AL11: 6924337955066903674 | AM11: X2501326322FXT | AP11: 儿童轻薄羽绒服 | AQ11: 橄榄绿;110 | AR11: 颜色分类:橄榄绿;尺码大小:110CM | AS11: 雪中飞 | AT11: 涛源 | AY11: 179 | AZ11: 86.7 | BA11: 普通商品资料成本价 | BB11: 1 | BD11: 1 | BE11: 179 | BF11: 179 | BG11: 86.7 | BH11: 86.7 | BI11: 92.3 | BJ11: 51.564% | BK11: 179 | BL11: 179 | BM11: 179 | BN11: 179 | BU11: 0 | BW11: 15 | BX11: 15 | BZ11: 0.36 | CA11: 0.36 | CB11: 头条放心购 | CC11: TOUTIAOFXG | CE11: 98.2 | CF11: =BD11-BP11 -> 1 | CG11: 179 | CH11: =_xlfn.XLOOKUP(AL11,抖音账单汇总!$A:$A,抖音账单汇总!$B:$B) -> 179
A12: 21069880 | B12: 小店,店铺新客,抖音,高频购买 | D12: 普通订单 | E12: 6950735723996321284 | G12: 已发货 | H12: 河北贝吉实业集团有限公司 | K12: 抖音-雪中飞德煌童装专卖店 | L12: 1@#g5MLuOx4qSHSIr71V4yoBqFTjGEPD1qVTEZb63/8yZOTRYKTJ4zQh2XkoS0l9isHERwCqn9ytP4= | M12: 13885096 | P12: 2026/2/12 23:20:20 | Q12: 2026/2/13 10:29:26 | R12: 2026/2/12 23:20:28 | S12: 2026/2/20 10:29:29 | T12: 2026/2/12 23:20:28 | U12: 河南省 | V12: 周口市 | W12: 商水县 | X12: 京东快递 | Y12: JDAZ23813815879 | AB12: 147:武* | AJ12: I568150018700 | AK12: 3787311554958066065 | AL12: 6950735723996321284 | AM12: X2501326322FXT | AP12: 儿童轻薄羽绒服 | AQ12: 橄榄绿;170 | AR12: 颜色分类:橄榄绿;尺码大小:170CM | AS12: 雪中飞 | AT12: 涛源 | AY12: 179 | AZ12: 86.7 | BA12: 普通商品资料成本价 | BB12: 1 | BD12: 1 | BE12: 179 | BF12: 179 | BG12: 86.7 | BH12: 86.7 | BI12: 92.3 | BJ12: 51.564% | BK12: 179 | BL12: 179 | BM12: 179 | BN12: 179 | BU12: 0 | BW12: 15 | BX12: 15 | BZ12: 0.537 | CA12: 0.537 | CB12: 头条放心购 | CC12: TOUTIAOFXG | CE12: 98.2 | CF12: =BD12-BP12 -> 1 | CG12: 179 | CH12: =_xlfn.XLOOKUP(AL12,抖音账单汇总!$A:$A,抖音账单汇总!$B:$B) -> 179
A13: 21068764 | B13: 小店,店铺新客,抖音,高频购买 | D13: 普通订单 | E13: 6950719343804749677 | G13: 已发货 | H13: 河北贝吉实业集团有限公司 | K13: 抖音-雪中飞德煌童装专卖店 | L13: 1@#+j8NsD5qsCReOUshndIinM9Opo2LWXKOJ/H10yf5nTXTQoYqizxKSBQqIwfe+6/RKIZ2NA== | M13: 13884280 | P13: 2026/2/12 20:48:46 | Q13: 2026/2/13 11:01:50 | R13: 2026/2/12 20:49:09 | S13: 2026/2/20 11:01:52 | T13: 2026/2/12 20:49:09 | U13: 湖南省 | V13: 衡阳市 | W13: 衡东县 | X13: 京东快递 | Y13: JDAZ23813829576 | AB13: 147:龙* | AJ13: I568150018600 | AK13: 3779048132244013371 | AL13: 6950719343804749677 | AM13: X2501326322FXT | AP13: 儿童轻薄羽绒服 | AQ13: 橄榄绿;160 | AR13: 颜色分类:橄榄绿;尺码大小:160CM | AS13: 雪中飞 | AT13: 涛源 | AY13: 179 | AZ13: 86.7 | BA13: 普通商品资料成本价 | BB13: 1 | BD13: 1 | BE13: 179 | BF13: 179 | BG13: 86.7 | BH13: 86.7 | BI13: 92.3 | BJ13: 51.564% | BK13: 179 | BL13: 179 | BM13: 179 | BN13: 179 | BU13: 0 | BW13: 15 | BX13: 15 | BZ13: 0.506 | CA13: 0.506 | CB13: 头条放心购 | CC13: TOUTIAOFXG | CE13: 98.2 | CF13: =BD13-BP13 -> 1 | CG13: 179 | CH13: =_xlfn.XLOOKUP(AL13,抖音账单汇总!$A:$A,抖音账单汇总!$B:$B) -> 179
A14: 21068046 | B14: 小店,店铺新客,抖音,服务优先,直播间 | D14: 普通订单 | E14: 6950739525784048859 | G14: 已发货 | H14: 河北贝吉实业集团有限公司 | K14: 抖音-雪中飞德煌童装专卖店 | L14: 1@#KBXQLJN7CoL9lgCw5yOGnqe/CgB1tjAxi2+vFLAJNqmkOq04csDO49Bhjwp37mo2dffqF07ZHw== | M14: 13883713 | P14: 2026/2/12 18:32:55 | Q14: 2026/2/13 11:10:56 | R14: 2026/2/12 18:33:03 | S14: 2026/2/20 11:10:59 | T14: 2026/2/12 18:33:03 | U14: 湖北省 | V14: 黄冈市 | W14: 英山县 | X14: 京东快递 | Y14: JDAZ23813790499 | AB14: 147:伍* | AJ14: H493814417402 | AK14: 3787311554958066065 | AL14: 6950739525784048859 | AM14: X250138240FXT | AN14: 羽绒服 | AP14: 儿童轻薄羽绒服 | AQ14: 黑色;140 | AR14: 颜色分类:黑色（8240款）;尺码大小:140CM | AS14: 雪中飞 | AT14: 茸淳羽绒 | AW14: 每日加权 | AY14: 179 | AZ14: 87 | BA14: 普通商品资料成本价 | BB14: 1 | BD14: 1 | BE14: 159 | BF14: 159 | BG14: 87 | BH14: 87 | BI14: 72 | BJ14: 45.283% | BK14: 159 | BL14: 159 | BM14: 159 | BN14: 159 | BU14: 0 | BW14: 15 | BX14: 15 | BZ14: 0.4655 | CA14: 0.4655 | CB14: 头条放心购 | CC14: TOUTIAOFXG | CE14: 98.5 | CF14: =BD14-BP14 -> 1 | CG14: 159 | CH14: =_xlfn.XLOOKUP(AL14,抖音账单汇总!$A:$A,抖音账单汇总!$B:$B) -> 159
A15: 21067952 | B15: 小店,店铺新客,抖音,直播间,高频购买 | D15: 普通订单 | E15: 6950725986157138995 | G15: 已发货 | H15: 河北贝吉实业集团有限公司 | K15: 抖音-雪中飞德煌童装专卖店 | L15: 1@#P1I6Sq+B3fkweBiXZ2UZc3ZRaXi1D71WLGlf9neQPJU2/4ynlZCk+0jSI+Z4F1UUeS/H | M15: 13883640 | P15: 2026/2/12 18:12:20 | Q15: 2026/2/13 10:29:34 | R15: 2026/2/12 18:12:21 | S15: 2026/2/20 10:29:35 | T15: 2026/2/12 18:12:21 | U15: 甘肃省 | V15: 庆阳市 | W15: 西峰区 | X15: 京东快递 | Y15: JDAZ23813790462 | AB15: 147:杨* | AJ15: I568150018700 | AK15: 3787311554958066065 | AL15: 6950725986157138995 | AM15: X2501326322FXT | AP15: 儿童轻薄羽绒服 | AQ15: 橄榄绿;170 | AR15: 颜色分类:橄榄绿;尺码大小:170CM | AS15: 雪中飞 | AT15: 涛源 | AY15: 179 | AZ15: 86.7 | BA15: 普通商品资料成本价 | BB15: 1 | BD15: 1 | BE15: 179 | BF15: 179 | BG15: 86.7 | BH15: 86.7 | BI15: 92.3 | BJ15: 51.564% | BK15: 179 | BL15: 179 | BM15: 179 | BN15: 179 | BU15: 0 | BW15: 15 | BX15: 15 | BZ15: 0.537 | CA15: 0.537 | CB15: 头条放心购 | CC15: TOUTIAOFXG | CE15: 98.2 | CF15: =BD15-BP15 -> 1 | CG15: 179 | CH15: =_xlfn.XLOOKUP(AL15,抖音账单汇总!$A:$A,抖音账单汇总!$B:$B) -> 179
A16: 20053626 | B16: 优先发货,发货后售后,小店,平台补贴,店铺新客,抖音,直播间,高频购买 | C16: 1226358737 | D16: 普通订单 | E16: 6923661839766748780 | G16: 已发货 | H16: 河北贝吉实业集团有限公司 | K16: 抖音-雪中飞德煌童装专卖店 | L16: 1@#QqH0gZYSdwx+A/cCDRAmn0118Gv7ryEGvA/bSREMrUboeTvhz4tjgOwv2CQsXOKnfGFD | M16: 13136948 | O16: cp8不评 ，15点红云,(收) 橄榄绿;160I568150018600*1# | P16: 2026/1/16 20:12:32 | Q16: 2026/1/17 8:48:46 | R16: 2026/1/16 20:12:33 | S16: 2026/1/24 8:48:47 | T16: 2026/1/16 20:12:33 | U16: 河北省 | V16: 邢台市 | W16: 宁晋县 | X16: 圆通速递 | Y16: YT0006642273225 | Z16: 中通快递 | AA16: 73595104410153 | AB16: 147:铱* | AC16: 2026/2/5 1:02:08 | AD16: 2026/2/10 13:44:47 | AE16: 2026-02-10 13:44:41 | AF16: 20243528 | AG16: 河北贝吉实业集团有限公司 | AH16: 普通退货 | AI16: 多拍/错拍/不想要 | AJ16: I568150018140 | AK16: 3787311554958066065 | AL16: 6923661839766748780 | AM16: X2501326322FXT | AP16: 儿童轻薄羽绒服 | AQ16: 橄榄绿;150 | AR16: 颜色分类:橄榄绿;尺码大小:150CM | AS16: 雪中飞 | AT16: 涛源 | AY16: 179 | AZ16: 86.7 | BA16: 普通商品资料成本价 | BB16: 1 | BD16: 1 | BE16: 179 | BF16: 179 | BG16: 86.7 | BH16: 86.7 | BI16: 92.3 | BJ16: 51.564% | BK16: 179 | BL16: 179 | BM16: 179 | BN16: 179 | BO16: 1 | BQ16: 179 | BR16: 86.7 | BU16: 0 | BW16: 3.6 | BX16: 3.6 | BZ16: 0.481 | CA16: 0.481 | CB16: 头条放心购 | CC16: TOUTIAOFXG | CE16: 98.2 | CF16: -1 | CG16: -179 | CH16: =_xlfn.XLOOKUP(AL16,抖音账单汇总!$A:$A,抖音账单汇总!$B:$B) -> -179
A17: 21067210 | B17: 小店,平台补贴,店铺新客,抖音,极速发货,直播间,高频购买 | D17: 普通订单 | E17: 6950735340405658797 | G17: 已发货 | H17: 河北贝吉实业集团有限公司 | K17: 抖音-雪中飞德煌童装专卖店 | L17: 1@#4Z+yBV4Qyscp/oBBgBga25Vc598Uxt9s2OLax8K+drEsD+TXHQqXD3vTsMfxGDlzOX6baVSKP9Q= | M17: 13883118 | P17: 2026/2/12 16:13:12 | Q17: 2026/2/12 17:20:05 | R17: 2026/2/12 16:13:13 | S17: 2026/2/19 17:20:06 | T17: 2026/2/12 16:13:13 | U17: 河南省 | V17: 安阳市 | W17: 文峰区 | X17: 京东快递 | Y17: JDAZ23804663869 | AB17: 147:王* | AJ17: H493814417140 | AK17: 3787311554958066065 | AL17: 6950735340405658797 | AM17: X250138240FXT | AN17: 羽绒服 | AP17: 儿童轻薄羽绒服 | AQ17: 黑色;150 | AR17: 颜色分类:黑色（8240款）;尺码大小:150CM | AS17: 雪中飞 | AT17: 茸淳羽绒 | AW17: 每日加权 | AY17: 179 | AZ17: 87 | BA17: 普通商品资料成本价 | BB17: 1 | BD17: 1 | BE17: 159 | BF17: 159 | BG17: 87 | BH17: 87 | BI17: 72 | BJ17: 45.283% | BK17: 159 | BL17: 159 | BM17: 159 | BN17: 159 | BU17: 0 | BW17: 15 | BX17: 15 | BZ17: 0.493 | CA17: 0.493 | CB17: 头条放心购 | CC17: TOUTIAOFXG | CE17: 98.5 | CF17: =BD17-BP17 -> 1 | CG17: 159 | CH17: =_xlfn.XLOOKUP(AL17,抖音账单汇总!$A:$A,抖音账单汇总!$B:$B) -> 159
A18: 21067198 | B18: 发货后售后,小店,店铺新客,抖音,服务优先,极速发货,直播间,高频购买 | D18: 普通订单 | E18: 6924354549235416269 | G18: 已发货 | H18: 河北贝吉实业集团有限公司 | K18: 抖音-雪中飞德煌童装专卖店 | L18: 1@#0TRxVML4T67csFMl47CIoVSgSohi0ou6gPxwZdnX+ihZvhhZuEQEWM+z1wwAUdiLqMDB | M18: 13883107 | O18: (收) 颜色分类:橄榄绿;尺码大小:140cmI568150018402*1# | P18: 2026/2/12 16:11:02 | Q18: 2026/2/12 17:17:33 | R18: 2026/2/12 16:11:03 | S18: 2026/2/15 13:17:08 | T18: 2026/2/12 16:11:03 | U18: 四川省 | V18: 成都市 | W18: 新都区 | X18: 京东快递 | Y18: JDAZ23804750656 | AB18: 147:汪* | AJ18: I568150018402 | AK18: 3787311554958066065 | AL18: 6924354549235416269 | AM18: X2501326322FXT | AP18: 儿童轻薄羽绒服 | AQ18: 橄榄绿;140 | AR18: 颜色分类:橄榄绿;尺码大小:140CM | AS18: 雪中飞 | AT18: 涛源 | AY18: 179 | AZ18: 86.7 | BA18: 普通商品资料成本价 | BB18: 1 | BD18: 1 | BE18: 179 | BF18: 179 | BG18: 86.7 | BH18: 86.7 | BI18: 92.3 | BJ18: 51.564% | BK18: 179 | BL18: 179 | BM18: 179 | BN18: 179 | BU18: 0 | BW18: 15 | BX18: 15 | BZ18: 0.456 | CA18: 0.456 | CB18: 头条放心购 | CC18: TOUTIAOFXG | CE18: 98.2 | CF18: =BD18-BP18 -> 1 | CG18: 179 | CH18: =_xlfn.XLOOKUP(AL18,抖音账单汇总!$A:$A,抖音账单汇总!$B:$B) -> 179
A19: 21067069 | B19: 小店,店铺新客,服务优先,极速发货,直播间,线上修改地址,高频购买 | D19: 普通订单 | E19: 6950733011866097255 | G19: 已发货 | H19: 河北贝吉实业集团有限公司 | K19: 抖音-雪中飞德煌童装专卖店 | L19: 1@#UdW2AvezOzHdIFPFBp0ZkxEZLuR2FPLB3A/wowgisAKw0Hva6YHsnv2Az+r/4YCWl1yxUuE+rNM= | M19: 13883005 | P19: 2026/2/12 15:54:03 | Q19: 2026/2/12 17:20:16 | R19: 2026/2/12 15:54:20 | S19: 2026/2/19 17:20:18 | T19: 2026/2/12 15:54:20 | U19: 河北省 | V19: 衡水市 | W19: 景县 | X19: 京东快递 | Y19: JDAZ23804698760 | AB19: 147:李* | AJ19: I568150018600 | AK19: 3787311554958066065 | AL19: 6950733011866097255 | AM19: X2501326322FXT | AP19: 儿童轻薄羽绒服 | AQ19: 橄榄绿;160 | AR19: 颜色分类:橄榄绿;尺码大小:160CM | AS19: 雪中飞 | AT19: 涛源 | AY19: 179 | AZ19: 86.7 | BA19: 普通商品资料成本价 | BB19: 1 | BD19: 1 | BE19: 179 | BF19: 179 | BG19: 86.7 | BH19: 86.7 | BI19: 92.3 | BJ19: 51.564% | BK19: 179 | BL19: 179 | BM19: 179 | BN19: 179 | BU19: 0 | BW19: 15 | BX19: 15 | BZ19: 0.506 | CA19: 0.506 | CB19: 头条放心购 | CC19: TOUTIAOFXG | CE19: 98.2 | CF19: =BD19-BP19 -> 1 | CG19: 179 | CH19: =_xlfn.XLOOKUP(AL19,抖音账单汇总!$A:$A,抖音账单汇总!$B:$B) -> 179
A20: 21066954 | B20: 小店,店铺新客,抖音极速版,直播间,线上修改地址,高频购买 | D20: 普通订单 | E20: 6924339630726282713 | G20: 已发货 | H20: 河北贝吉实业集团有限公司 | K20: 抖音-雪中飞德煌童装专卖店 | L20: 1@#PB5AZcZ/2+wXuvNVPLAT8CVsDq4oLjD5phzstM8VE/lN2WY3VwjbfFb3yw13D7UyJgyIVNu8yUo= | M20: 13882937 | P20: 2026/2/12 15:40:16 | Q20: 2026/2/12 16:24:42 | R20: 2026/2/12 15:40:30 | S20: 2026/2/19 16:24:44 | T20: 2026/2/12 15:40:30 | U20: 河南省 | V20: 商丘市 | W20: 柘城县 | X20: 京东快递 | Y20: JDAZ23803065479 | AB20: 147:吴* | AJ20: H598714417164 | AK20: 3787311554958066065 | AL20: 6924339630726282713 | AM20: X250138648FXT | AN20: 轻薄羽绒服 | AP20: 儿童轻薄羽绒服 | AQ20: 黑色;120 | AR20: 颜色分类:黑色（8648款）;尺码大小:120CM | AS20: 雪中飞 | AT20: 贝优 | AW20: 每日加权 | AY20: 179 | AZ20: 85.5 | BA20: 普通商品资料成本价 | BB20: 1 | BD20: 1 | BE20: 179 | BF20: 179 | BG20: 85.5 | BH20: 85.5 | BI20: 93.5 | BJ20: 52.235% | BK20: 179 | BL20: 179 | BM20: 179 | BN20: 179 | BU20: 0 | BW20: 15 | BX20: 15 | BZ20: 0.385 | CA20: 0.385 | CB20: 头条放心购 | CC20: TOUTIAOFXG | CE20: 97 | CF20: =BD20-BP20 -> 1 | CG20: 179 | CH20: =_xlfn.XLOOKUP(AL20,抖音账单汇总!$A:$A,抖音账单汇总!$B:$B) -> 179
A21: 21064680 | B21: 小店,店铺新客,抖音,服务优先,极速发货,直播间 | D21: 普通订单 | E21: 6950714426810242370 | G21: 已发货 | H21: 河北贝吉实业集团有限公司 | K21: 抖音-雪中飞德煌童装专卖店 | L21: 1@#/Txi9Y5TDAHjqnfA/bWCpWQWmOWXk1bxRjwEt3juduhij5HbLuyIUWM5kLB4HUBTd+Wh | M21: 13881244 | P21: 2026/2/12 10:53:49 | Q21: 2026/2/12 14:25:36 | R21: 2026/2/12 10:53:58 | S21: 2026/2/19 14:25:38 | T21: 2026/2/12 10:53:58 | U21: 四川省 | V21: 眉山市 | W21: 青神县 | X21: 京东快递 | Y21: JDAZ23799744126 | AB21: 147:文* | AJ21: I568150018140 | AK21: 3787311554958066065 | AL21: 6950714426810242370 | AM21: X2501326322FXT | AP21: 儿童轻薄羽绒服 | AQ21: 橄榄绿;150 | AR21: 颜色分类:橄榄绿;尺码大小:150CM | AS21: 雪中飞 | AT21: 涛源 | AY21: 179 | AZ21: 86.7 | BA21: 普通商品资料成本价 | BB21: 1 | BD21: 1 | BE21: 179 | BF21: 179 | BG21: 86.7 | BH21: 86.7 | BI21: 92.3 | BJ21: 51.564% | BK21: 179 | BL21: 179 | BM21: 179 | BN21: 179 | BU21: 0 | BW21: 15 | BX21: 15 | BZ21: 0.481 | CA21: 0.481 | CB21: 头条放心购 | CC21: TOUTIAOFXG | CE21: 98.2 | CF21: =BD21-BP21 -> 1 | CG21: 179 | CH21: =_xlfn.XLOOKUP(AL21,抖音账单汇总!$A:$A,抖音账单汇总!$B:$B) -> 179
A22: 21064565 | B22: 小店,店铺新客,抖音,服务优先,直播间 | D22: 普通订单 | E22: 6924333026177875241 | G22: 已发货 | H22: 河北贝吉实业集团有限公司 | K22: 抖音-雪中飞德煌童装专卖店 | L22: 1@#7bfqJnxLKOn+Z4I09thb22fDHiGhKbG9NqmwHpwGMDRXdwg2I3dcFYx/GA5zqgnE5GtRLQ== | M22: 13881174 | P22: 2026/2/12 10:41:55 | Q22: 2026/2/12 14:54:01 | R22: 2026/2/12 10:42:26 | S22: 2026/2/19 14:54:03 | T22: 2026/2/12 10:42:26 | U22: 江苏省 | V22: 常州市 | W22: 武进区 | X22: 京东快递 | Y22: JDAZ23799637052 | AB22: 147:许* | AJ22: I568150018700 | AK22: 3787311554958066065 | AL22: 6924333026177875241 | AM22: X2501326322FXT | AP22: 儿童轻薄羽绒服 | AQ22: 橄榄绿;170 | AR22: 颜色分类:橄榄绿;尺码大小:170CM | AS22: 雪中飞 | AT22: 涛源 | AY22: 179 | AZ22: 86.7 | BA22: 普通商品资料成本价 | BB22: 1 | BD22: 1 | BE22: 179 | BF22: 179 | BG22: 86.7 | BH22: 86.7 | BI22: 92.3 | BJ22: 51.564% | BK22: 179 | BL22: 179 | BM22: 179 | BN22: 179 | BU22: 0 | BW22: 15 | BX22: 15 | BZ22: 0.537 | CA22: 0.537 | CB22: 头条放心购 | CC22: TOUTIAOFXG | CE22: 98.2 | CF22: =BD22-BP22 -> 1 | CG22: 179 | CH22: =_xlfn.XLOOKUP(AL22,抖音账单汇总!$A:$A,抖音账单汇总!$B:$B) -> 179
A23: 21064561 | B23: 小店,店铺新客,抖音,极速发货,直播间 | D23: 普通订单 | E23: 6950743455072589518 | G23: 已发货 | H23: 河北贝吉实业集团有限公司 | K23: 抖音-雪中飞德煌童装专卖店 | L23: 1@#8MUr8M7J8XHPq9jZUKPQ/Sb7NYZyJgYM67FoRBC6UntKA4IqdPFdnz6xVh/1KP7U9VlroL758y8= | M23: 13881176 | P23: 2026/2/12 10:42:11 | Q23: 2026/2/12 14:24:05 | R23: 2026/2/12 10:42:15 | S23: 2026/2/19 14:24:06 | T23: 2026/2/12 10:42:15 | U23: 四川省 | V23: 达州市 | W23: 宣汉县 | X23: 京东快递 | Y23: JDAZ23799744071 | AB23: 147:爸* | AJ23: I568150018402 | AK23: 3787311554958066065 | AL23: 6950743455072589518 | AM23: X2501326322FXT | AP23: 儿童轻薄羽绒服 | AQ23: 橄榄绿;140 | AR23: 颜色分类:橄榄绿;尺码大小:140CM | AS23: 雪中飞 | AT23: 涛源 | AY23: 179 | AZ23: 86.7 | BA23: 普通商品资料成本价 | BB23: 1 | BD23: 1 | BE23: 179 | BF23: 179 | BG23: 86.7 | BH23: 86.7 | BI23: 92.3 | BJ23: 51.564% | BK23: 179 | BL23: 179 | BM23: 179 | BN23: 179 | BU23: 0 | BW23: 15 | BX23: 15 | BZ23: 0.456 | CA23: 0.456 | CB23: 头条放心购 | CC23: TOUTIAOFXG | CE23: 98.2 | CF23: =BD23-BP23 -> 1 | CG23: 179 | CH23: =_xlfn.XLOOKUP(AL23,抖音账单汇总!$A:$A,抖音账单汇总!$B:$B) -> 179
A24: 21064523 | B24: 小店,店铺新客,抖音,极速发货,直播间,高频购买 | D24: 普通订单 | E24: 6924341239823301947 | G24: 已发货 | H24: 河北贝吉实业集团有限公司 | K24: 抖音-雪中飞德煌童装专卖店 | L24: 1@#aWC+XDVok/b91foqffC2nz8CXpR3S0AZROSLrVSmxH0wYl9ZUPVPFxqTPVFz7P2H/+Tq | M24: 13881145 | P24: 2026/2/12 10:39:11 | Q24: 2026/2/12 14:24:27 | R24: 2026/2/12 10:39:13 | S24: 2026/2/19 14:24:30 | T24: 2026/2/12 10:39:13 | U24: 甘肃省 | V24: 平凉市 | W24: 静宁县 | X24: 京东快递 | Y24: JDAZ23799647150 | AB24: 147:唐* | AJ24: H493814417140 | AK24: 3787311554958066065 | AL24: 6924341239823301947 | AM24: X250138240FXT | AN24: 羽绒服 | AP24: 儿童轻薄羽绒服 | AQ24: 黑色;150 | AR24: 颜色分类:黑色（8240款）;尺码大小:150CM | AS24: 雪中飞 | AT24: 茸淳羽绒 | AW24: 每日加权 | AY24: 179 | AZ24: 87 | BA24: 普通商品资料成本价 | BB24: 1 | BD24: 1 | BE24: 159 | BF24: 159 | BG24: 87 | BH24: 87 | BI24: 72 | BJ24: 45.283% | BK24: 159 | BL24: 159 | BM24: 159 | BN24: 159 | BU24: 0 | BW24: 15 | BX24: 15 | BZ24: 0.493 | CA24: 0.493 | CB24: 头条放心购 | CC24: TOUTIAOFXG | CE24: 98.5 | CF24: =BD24-BP24 -> 1 | CG24: 159 | CH24: =_xlfn.XLOOKUP(AL24,抖音账单汇总!$A:$A,抖音账单汇总!$B:$B) -> 159
A25: 21064413 | B25: 小店,店铺新客,抖音,极速发货,直播间 | D25: 普通订单 | E25: 6924343450946141328 | G25: 已发货 | H25: 河北贝吉实业集团有限公司 | K25: 抖音-雪中飞德煌童装专卖店 | L25: 1@#tylngmqou5oBjV0Bs+W9m4PktvK6uNN2dCGfpaqv/ieWqaUufFuoWk57KbT8yzsklUiQ | M25: 13881065 | O25: hp反8【栀 03-02 10:56】 | P25: 2026/2/12 10:27:41 | Q25: 2026/2/12 14:25:24 | R25: 2026/2/12 10:27:45 | S25: 2026/2/19 14:25:25 | T25: 2026/2/12 10:27:45 | U25: 山东省 | V25: 济南市 | W25: 章丘区 | X25: 京东快递 | Y25: JDAZ23799629205 | AB25: 147:杨* | AJ25: I568150018140 | AK25: 3787311554958066065 | AL25: 6924343450946141328 | AM25: X2501326322FXT | AP25: 儿童轻薄羽绒服 | AQ25: 橄榄绿;150 | AR25: 颜色分类:橄榄绿;尺码大小:150CM | AS25: 雪中飞 | AT25: 涛源 | AY25: 179 | AZ25: 86.7 | BA25: 普通商品资料成本价 | BB25: 1 | BD25: 1 | BE25: 179 | BF25: 179 | BG25: 86.7 | BH25: 86.7 | BI25: 92.3 | BJ25: 51.564% | BK25: 179 | BL25: 179 | BM25: 179 | BN25: 179 | BU25: 0 | BW25: 15 | BX25: 15 | BZ25: 0.481 | CA25: 0.481 | CB25: 头条放心购 | CC25: TOUTIAOFXG | CE25: 98.2 | CF25: =BD25-BP25 -> 1 | CG25: 179 | CH25: =_xlfn.XLOOKUP(AL25,抖音账单汇总!$A:$A,抖音账单汇总!$B:$B) -> 179
A26: 21064094 | B26: 小店,店铺新客,抖音,服务优先,直播间,高频购买 | D26: 普通订单 | E26: 6924341217322696219 | G26: 已发货 | H26: 河北贝吉实业集团有限公司 | K26: 抖音-雪中飞德煌童装专卖店 | L26: 1@#9SkKjUZXzAg8RE5igbXGu+1tbG5EH7A65JQbTpqMF5fscDBP5Kx1ikCa04fJHqfLNmU9 | M26: 13880822 | P26: 2026/2/12 9:55:05 | Q26: 2026/2/12 14:25:17 | R26: 2026/2/12 9:55:07 | S26: 2026/2/19 14:25:21 | T26: 2026/2/12 9:55:07 | U26: 北京 | V26: 北京市 | W26: 海淀区 | X26: 京东快递 | Y26: JDAZ23799672260 | AB26: 147:月* | AJ26: I568150018140 | AK26: 3787311554958066065 | AL26: 6924341217322696219 | AM26: X2501326322FXT | AP26: 儿童轻薄羽绒服 | AQ26: 橄榄绿;150 | AR26: 颜色分类:橄榄绿;尺码大小:150CM | AS26: 雪中飞 | AT26: 涛源 | AY26: 179 | AZ26: 86.7 | BA26: 普通商品资料成本价 | BB26: 1 | BD26: 1 | BE26: 179 | BF26: 179 | BG26: 86.7 | BH26: 86.7 | BI26: 92.3 | BJ26: 51.564% | BK26: 179 | BL26: 179 | BM26: 179 | BN26: 179 | BU26: 0 | BW26: 15 | BX26: 15 | BZ26: 0.481 | CA26: 0.481 | CB26: 头条放心购 | CC26: TOUTIAOFXG | CE26: 98.2 | CF26: =BD26-BP26 -> 1 | CG26: 179 | CH26: =_xlfn.XLOOKUP(AL26,抖音账单汇总!$A:$A,抖音账单汇总!$B:$B) -> 179
A27: 21063992 | B27: 小店,店铺新客,抖音极速版,服务优先,极速发货,直播间,高频购买 | D27: 普通订单 | E27: 6924347572239629550 | G27: 已发货 | H27: 河北贝吉实业集团有限公司 | K27: 抖音-雪中飞德煌童装专卖店 | L27: 1@#jq0Ay/w86ur/DRaGwETF5W3fY1gtfn/CrYGkBS0ttDpkTBup/e6MJdUULrogUGyQpFfgEQ== | M27: 13880755 | P27: 2026/2/12 9:45:12 | Q27: 2026/2/12 15:18:21 | R27: 2026/2/12 9:45:16 | S27: 2026/2/19 15:18:23 | T27: 2026/2/12 9:45:16 | U27: 广西壮族自治区 | V27: 南宁市 | W27: 西乡塘区 | X27: 京东快递 | Y27: JDAZ23799703913 | AB27: 147:顺* | AJ27: I568150018600 | AK27: 3787311554958066065 | AL27: 6924347572239629550 | AM27: X2501326322FXT | AP27: 儿童轻薄羽绒服 | AQ27: 橄榄绿;160 | AR27: 颜色分类:橄榄绿;尺码大小:160CM | AS27: 雪中飞 | AT27: 涛源 | AY27: 179 | AZ27: 86.7 | BA27: 普通商品资料成本价 | BB27: 1 | BD27: 1 | BE27: 179 | BF27: 179 | BG27: 86.7 | BH27: 86.7 | BI27: 92.3 | BJ27: 51.564% | BK27: 179 | BL27: 179 | BM27: 179 | BN27: 179 | BU27: 0 | BW27: 15 | BX27: 15 | BZ27: 0.506 | CA27: 0.506 | CB27: 头条放心购 | CC27: TOUTIAOFXG | CE27: 98.2 | CF27: =BD27-BP27 -> 1 | CG27: 179 | CH27: =_xlfn.XLOOKUP(AL27,抖音账单汇总!$A:$A,抖音账单汇总!$B:$B) -> 179
A28: 21063883 | B28: 小店,平台补贴,店铺新客,抖音,极速发货,直播间,高频购买 | D28: 普通订单 | E28: 6950723299436991679 | G28: 已发货 | H28: 河北贝吉实业集团有限公司 | K28: 抖音-雪中飞德煌童装专卖店 | L28: 1@#5H5o07ydxX0gIH/xiDHrSxM7+JOX6vPsUH2hH07bjdeGDYFnmkYtOVRNWbJhNmR79uAI | M28: 13880679 | P28: 2026/2/12 9:36:22 | Q28: 2026/2/12 15:07:31 | R28: 2026/2/12 9:36:26 | S28: 2026/2/19 15:07:34 | T28: 2026/2/12 9:36:26 | U28: 湖北省 | V28: 黄冈市 | W28: 麻城市 | X28: 京东快递 | Y28: JDAZ23799647186 | AB28: 147:何* | AJ28: I568150018302 | AK28: 3787311554958066065 | AL28: 6950723299436991679 | AM28: X2501326322FXT | AP28: 儿童轻薄羽绒服 | AQ28: 橄榄绿;130 | AR28: 颜色分类:橄榄绿;尺码大小:130CM | AS28: 雪中飞 | AT28: 涛源 | AY28: 179 | AZ28: 86.7 | BA28: 普通商品资料成本价 | BB28: 1 | BD28: 1 | BE28: 179 | BF28: 179 | BG28: 86.7 | BH28: 86.7 | BI28: 92.3 | BJ28: 51.564% | BK28: 179 | BL28: 179 | BM28: 179 | BN28: 179 | BU28: 0 | BW28: 15 | BX28: 15 | BZ28: 0.419 | CA28: 0.419 | CB28: 头条放心购 | CC28: TOUTIAOFXG | CE28: 98.2 | CF28: =BD28-BP28 -> 1 | CG28: 179 | CH28: =_xlfn.XLOOKUP(AL28,抖音账单汇总!$A:$A,抖音账单汇总!$B:$B) -> 179
A29: 21063874 | B29: 小店,店铺老客,抖音极速版,消费者催发货,高频购买 | D29: 普通订单 | E29: 6924339142331891449 | G29: 已发货 | H29: 河北贝吉实业集团有限公司 | K29: 抖音-雪中飞德煌童装专卖店 | L29: 1@#HKjtaKoQ4doLbMWHOExpSRFJ4WropYDd1kThpAIQkRjiMXia2qTftab9H/Js6z7dYJdc | M29: 13880457 | P29: 2026/2/12 9:35:36 | Q29: 2026/2/12 15:17:53 | R29: 2026/2/12 9:35:50 | S29: 2026/2/16 20:55:11 | T29: 2026/2/12 9:35:50 | U29: 贵州省 | V29: 遵义市 | W29: 汇川区 | X29: 京东快递 | Y29: JDAZ23799637009 | AB29: 147:艳* | AJ29: I568150018600 | AK29: 3787311554958066065 | AL29: 6924339142331891449 | AM29: X2501326322FXT | AP29: 儿童轻薄羽绒服 | AQ29: 橄榄绿;160 | AR29: 颜色分类:橄榄绿;尺码大小:160CM | AS29: 雪中飞 | AT29: 涛源 | AY29: 179 | AZ29: 86.7 | BA29: 普通商品资料成本价 | BB29: 1 | BD29: 1 | BE29: 179 | BF29: 179 | BG29: 86.7 | BH29: 86.7 | BI29: 92.3 | BJ29: 51.564% | BK29: 179 | BL29: 179 | BM29: 179 | BN29: 179 | BU29: 0 | BW29: 15 | BX29: 15 | BZ29: 0.506 | CA29: 0.506 | CB29: 头条放心购 | CC29: TOUTIAOFXG | CE29: 98.2 | CF29: =BD29-BP29 -> 1 | CG29: 179 | CH29: =_xlfn.XLOOKUP(AL29,抖音账单汇总!$A:$A,抖音账单汇总!$B:$B) -> 179
A30: 21063775 | B30: 小店,平台补贴,店铺新客,服务优先,极速发货,直播间,高频购买 | D30: 普通订单 | E30: 6924347607424138364 | G30: 已发货 | H30: 河北贝吉实业集团有限公司 | K30: 抖音-雪中飞德煌童装专卖店 | L30: 1@#NuGvpqkvbQVwoh5Gk5E+nfMuWuL1s+s8rbO0mFH/QwhJaXVbNoD8vaawo2+Smad25bDURg== | M30: 13880545 | O30: hp8 【叙源 02-26 10:48】 | P30: 2026/2/12 9:15:18 | Q30: 2026/2/12 14:28:45 | R30: 2026/2/12 9:23:49 | S30: 2026/2/19 14:28:49 | T30: 2026/2/12 9:23:49 | U30: 河南省 | V30: 漯河市 | W30: 召陵区 | X30: 京东快递 | Y30: JDAZ23799671900 | AB30: 147:姚* | AJ30: I180852187700 | AK30: 3779552986313916499 | AL30: 6924347607424138364 | AM30: X2501324376FXT | AN30: 羽绒服 | AP30: 儿童轻薄羽绒服 | AQ30: 新嫩黄;170 | AR30: 颜色分类:新嫩黄;尺码大小:170 | AS30: 雪中飞 | AT30: 华衫 | AY30: 179 | AZ30: 76 | BA30: 普通商品资料成本价 | BB30: 1 | BD30: 1 | BE30: 179 | BF30: 179 | BG30: 76 | BH30: 76 | BI30: 103 | BJ30: 57.542% | BK30: 179 | BL30: 179 | BM30: 179 | BN30: 179 | BU30: 0 | BW30: 15 | BX30: 15 | BZ30: 0.488 | CA30: 0.488 | CB30: 头条放心购 | CC30: TOUTIAOFXG | CE30: 87.5 | CF30: =BD30-BP30 -> 1 | CG30: 179 | CH30: =_xlfn.XLOOKUP(AL30,抖音账单汇总!$A:$A,抖音账单汇总!$B:$B) -> 179
A31: 21063714 | B31: 小店,店铺新客,抖音,服务优先,极速发货,直播间,高频购买 | D31: 普通订单 | E31: 6924343325591305750 | G31: 已发货 | H31: 河北贝吉实业集团有限公司 | K31: 抖音-雪中飞德煌童装专卖店 | L31: 1@#ANen5HipxsFlcq8n3PGxMepIoMvXzgo/2geyi5k4zOfH5fDwhEIYHwfnMN8mjOo9ZnkFonu0f68= | M31: 13880547 | P31: 2026/2/12 9:15:44 | Q31: 2026/2/12 14:23:42 | R31: 2026/2/12 9:15:51 | S31: 2026/2/19 14:23:45 | T31: 2026/2/12 9:15:51 | U31: 湖北省 | V31: 宜昌市 | W31: 枝江市 | X31: 京东快递 | Y31: JDAZ23799671927 | AB31: 147:陈* | AJ31: I568150018402 | AK31: 3787311554958066065 | AL31: 6924343325591305750 | AM31: X2501326322FXT | AP31: 儿童轻薄羽绒服 | AQ31: 橄榄绿;140 | AR31: 颜色分类:橄榄绿;尺码大小:140CM | AS31: 雪中飞 | AT31: 涛源 | AY31: 179 | AZ31: 86.7 | BA31: 普通商品资料成本价 | BB31: 1 | BD31: 1 | BE31: 179 | BF31: 179 | BG31: 86.7 | BH31: 86.7 | BI31: 92.3 | BJ31: 51.564% | BK31: 179 | BL31: 179 | BM31: 179 | BN31: 179 | BU31: 0 | BW31: 15 | BX31: 15 | BZ31: 0.456 | CA31: 0.456 | CB31: 头条放心购 | CC31: TOUTIAOFXG | CE31: 98.2 | CF31: =BD31-BP31 -> 1 | CG31: 179 | CH31: =_xlfn.XLOOKUP(AL31,抖音账单汇总!$A:$A,抖音账单汇总!$B:$B) -> 179
A32: 21063712 | B32: 小店,平台补贴,店铺新客,抖音,极速发货,消费者催发货,直播间,线上修改地址,高频购买 | D32: 普通订单 | E32: 6950734975035840390 | G32: 已发货 | H32: 河北贝吉实业集团有限公司 | K32: 抖音-雪中飞德煌童装专卖店 | L32: 1@#O6poNV3ToZZoEKz9h5C5J3Qd7/C+OQjtp+IEDInx6SGdAp/dmTvVjRfExh/+JJ4r4aqs | M32: 13880540 | P32: 2026/2/12 9:15:08 | Q32: 2026/2/12 15:06:25 | R32: 2026/2/12 9:15:21 | S32: 2026/2/19 15:06:28 | T32: 2026/2/12 9:15:21 | U32: 安徽省 | V32: 亳州市 | W32: 蒙城县 | X32: 京东快递 | Y32: JDAZ23799629123 | AB32: 147:冯* | AJ32: I568150018302 | AK32: 3787311554958066065 | AL32: 6950734975035840390 | AM32: X2501326322FXT | AP32: 儿童轻薄羽绒服 | AQ32: 橄榄绿;130 | AR32: 颜色分类:橄榄绿;尺码大小:130CM | AS32: 雪中飞 | AT32: 涛源 | AY32: 179 | AZ32: 86.7 | BA32: 普通商品资料成本价 | BB32: 1 | BD32: 1 | BE32: 179 | BF32: 179 | BG32: 86.7 | BH32: 86.7 | BI32: 92.3 | BJ32: 51.564% | BK32: 179 | BL32: 179 | BM32: 179 | BN32: 179 | BU32: 0 | BW32: 15 | BX32: 15 | BZ32: 0.419 | CA32: 0.419 | CB32: 头条放心购 | CC32: TOUTIAOFXG | CE32: 98.2 | CF32: =BD32-BP32 -> 1 | CG32: 179 | CH32: =_xlfn.XLOOKUP(AL32,抖音账单汇总!$A:$A,抖音账单汇总!$B:$B) -> 179
A33: 21063600 | B33: 小店,店铺新客,极速发货,直播间,高频购买 | D33: 普通订单 | E33: 6924343311481535605 | G33: 已发货 | H33: 河北贝吉实业集团有限公司 | K33: 抖音-雪中飞德煌童装专卖店 | L33: 1@#s6MpDoOUAhLz4P9ynbsHB3yEOcAS7wI2ipo6s5PcjNTnMNiKTJKZfct7nK5/Ii3NvpaO | M33: 13877487 | P33: 2026/2/12 9:04:02 | Q33: 2026/2/12 14:24:43 | R33: 2026/2/12 9:04:23 | S33: 2026/2/19 14:24:44 | T33: 2026/2/12 9:04:23 | U33: 浙江省 | V33: 温州市 | W33: 瑞安市 | X33: 京东快递 | Y33: JDAZ23799704337 | AB33: 147:郭* | AJ33: I568150018140 | AK33: 3787311554958066065 | AL33: 6924343311481535605 | AM33: X2501326322FXT | AP33: 儿童轻薄羽绒服 | AQ33: 橄榄绿;150 | AR33: 颜色分类:橄榄绿;尺码大小:150CM | AS33: 雪中飞 | AT33: 涛源 | AY33: 179 | AZ33: 86.7 | BA33: 普通商品资料成本价 | BB33: 1 | BD33: 1 | BE33: 179 | BF33: 179 | BG33: 86.7 | BH33: 86.7 | BI33: 92.3 | BJ33: 51.564% | BK33: 179 | BL33: 179 | BM33: 179 | BN33: 179 | BU33: 0 | BW33: 15 | BX33: 15 | BZ33: 0.481 | CA33: 0.481 | CB33: 头条放心购 | CC33: TOUTIAOFXG | CE33: 98.2 | CF33: =BD33-BP33 -> 1 | CG33: 179 | CH33: =_xlfn.XLOOKUP(AL33,抖音账单汇总!$A:$A,抖音账单汇总!$B:$B) -> 179
A34: 21063599 | B34: 小店,已推送至供应商,店铺老客,抖音,直播间,高频购买 | D34: 普通订单,分销Plus | E34: 6924339128078401289 | G34: 已发货 | H34: ---- 未设定 ---- | K34: 抖音-雪中飞德煌童装专卖店 | L34: 1@#+OQ3mCftYUZ5vAw1VW6poGDpfFSHim0hdpuD1g84E9VhrlxrXUQ03kHjW8asHdCH8wrA | M34: 13821258 | P34: 2026/2/12 9:03:48 | Q34: 2026/2/12 17:14:14 | R34: 2026/2/12 9:04:04 | S34: 2026/2/19 17:14:17 | T34: 2026/2/12 9:04:04 | U34: 安徽省 | V34: 宣城市 | W34: 宣州区 | X34: 无极圆通速递公司 | Y34: YT0014766044546 | AB34: 147:王* | AJ34: I687051663823 | AK34: 3802578368348685236 | AL34: 6924339128078401289 | AM34: X2509329934FXT | AP34: 儿童裤子 | AQ34: 浅花灰;130 | AR34: 颜色分类:浅花灰;尺码大小:130 | AS34: 雪中飞 | AT34: 咔咔商贸 | AY34: 109 | AZ34: 40 | BA34: 分销单成本价 | BB34: 1 | BD34: 0 | BF34: 69.9 | BG34: 40 | BI34: 29.9 | BJ34: 42.775% | BK34: 69.9 | BL34: 69.9 | BM34: 69.9 | BN34: 69.9 | BU34: 0 | BZ34: 0 | CA34: 0 | CB34: 头条放心购 | CC34: TOUTIAOFXG | CF34: 1 | CG34: 69.9 | CH34: =_xlfn.XLOOKUP(AL34,抖音账单汇总!$A:$A,抖音账单汇总!$B:$B) -> 69.9
A35: 21063319 | B35: 发货后售后,小店,店铺新客,抖音极速版,直播间,高频购买 | D35: 普通订单 | E35: 6924347547891629873 | G35: 已发货 | H35: 河北贝吉实业集团有限公司 | K35: 抖音-雪中飞德煌童装专卖店 | L35: 1@#/hzCOxARPyqF6J75lPj9gVitCPQj5BzjmvQm2uaS4UrvtzznnTx78bP16wVLHdFEnSCl | M35: 13880285 | O35: (收) 颜色分类:橄榄绿;尺码大小:160cmI568150018600*1# | P35: 2026/2/12 8:42:13 | Q35: 2026/2/12 9:42:34 | R35: 2026/2/12 8:42:28 | S35: 2026/2/19 9:42:36 | T35: 2026/2/12 8:42:28 | U35: 江西省 | V35: 上饶市 | W35: 广丰区 | X35: 京东快递 | Y35: JDAZ23788744101 | AB35: 147:夏* | AJ35: I568150018600 | AK35: 3787311554958066065 | AL35: 6924347547891629873 | AM35: X2501326322FXT | AP35: 儿童轻薄羽绒服 | AQ35: 橄榄绿;160 | AR35: 颜色分类:橄榄绿;尺码大小:160CM | AS35: 雪中飞 | AT35: 涛源 | AY35: 179 | AZ35: 86.7 | BA35: 普通商品资料成本价 | BB35: 1 | BD35: 1 | BE35: 179 | BF35: 179 | BG35: 86.7 | BH35: 86.7 | BI35: 92.3 | BJ35: 51.564% | BK35: 179 | BL35: 179 | BM35: 179 | BN35: 179 | BU35: 0 | BW35: 15 | BX35: 15 | BZ35: 0.506 | CA35: 0.506 | CB35: 头条放心购 | CC35: TOUTIAOFXG | CE35: 98.2 | CF35: =BD35-BP35 -> 1 | CG35: 179 | CH35: =_xlfn.XLOOKUP(AL35,抖音账单汇总!$A:$A,抖音账单汇总!$B:$B) -> 179
A36: 21063153 | B36: 小店,平台补贴,店铺新客,抖音,服务优先,直播间 | D36: 普通订单 | E36: 6924332881092050522 | G36: 已发货 | H36: 河北贝吉实业集团有限公司 | K36: 抖音-雪中飞德煌童装专卖店 | L36: 1@#/nyQO3TpZ4bVtvFrFqqcaVOC7VftH7K7QBLPmR4g6BbwgGBDVh7BDuL/o2ErS2Lz0un2 | M36: 13880163 | P36: 2026/2/12 8:24:59 | Q36: 2026/2/12 9:39:40 | R36: 2026/2/12 8:25:00 | S36: 2026/2/17 2:39:00 | T36: 2026/2/12 8:25:00 | U36: 浙江省 | V36: 宁波市 | W36: 慈溪市 | X36: 京东快递 | Y36: JDAZ23788771317 | AB36: 147:高* | AJ36: I568150018140 | AK36: 3787311554958066065 | AL36: 6924332881092050522 | AM36: X2501326322FXT | AP36: 儿童轻薄羽绒服 | AQ36: 橄榄绿;150 | AR36: 颜色分类:橄榄绿;尺码大小:150CM | AS36: 雪中飞 | AT36: 涛源 | AY36: 179 | AZ36: 86.7 | BA36: 普通商品资料成本价 | BB36: 1 | BD36: 1 | BE36: 179 | BF36: 179 | BG36: 86.7 | BH36: 86.7 | BI36: 92.3 | BJ36: 51.564% | BK36: 179 | BL36: 179 | BM36: 179 | BN36: 179 | BU36: 0 | BW36: 15 | BX36: 15 | BZ36: 0.481 | CA36: 0.481 | CB36: 头条放心购 | CC36: TOUTIAOFXG | CE36: 98.2 | CF36: =BD36-BP36 -> 1 | CG36: 179 | CH36: =_xlfn.XLOOKUP(AL36,抖音账单汇总!$A:$A,抖音账单汇总!$B:$B) -> 179
